Workbook
Name _Hlk231065246: 'DATOS GENERALES'!$H$165

Sheet DATOS GENERALES
A1: FECHA | B1: NOMBRE COMPLETO | C1: ID/CC/DNI | D1: PASAPORTE | E1: PAIS | F1: ESTADO | G1: CIUDAD | H1: DIRECCION | I1: COD POSTAL | J1: CORREO | K1: TELEFONO | L1: TELEGRAM | M1: PRODUCTO / MATERIAL | N1: MONTO | O1: REF | P1: BANK | Q1: LIDER | R1: CIS/ MANDATE | S1: PASAPORTE + 3 MESES | T1: PASAPORTES QUE VENCEN EN 2026
A2: 45918.771 | B2: ALEJANDRA GALLEGO RAMÍREZ | C2: 1088244700 | D2: N/A | E2: COLOMBIA | F2: RISARALDA | G2: PEREIRA | H2: CALLE 67 N 26 55 CUBA | I2: 660005 | J2: alejandragallegoramirez@yahoo.es | K2: (+57) 3146792869 | L2: @ALEJA1324 | M2: 1Q+1N+2V | N2: 200000 | O2: M5603677 | P2: NEQUI | Q2: JOHANA CASTAÑEDA | R2: ENVIADO | S2: N/A
A3: 46114 | B3: ALEJANDRA MARIA BETANCUR OSORIO | C3: 25235412 | D3: BD328207 | E3: COLOMBIA | F3: ANTIOQUIA | G3: MEDELLIN | H3: CR 78A CL 52 SUR - 76 INTERIOR 3 | I3: 050018 | J3: aleja.betos101178@gmail.com | K3: (+57) 3146253152 | L3: @AlejaBetos | M3: 2Q+1V | N3: 100000 | O3: M18737535 | P3: NEQUI | Q3: JOHANA CASTAÑEDA | R3: ENVIADO | S3: VIGENTE
A4: 45817.615 | B4: ALEXANDER MARIN CASTAÑEDA | C4: 10018741 | D4: AT116472 | E4: COLOMBIA | F4: RISARALDA | G4: PEREIRA | H4: CLL 86 # 38 A 08 MZ 11 CS 2 | I4: 660001 | J4: almariny@gmail.com | K4: (+57) 3007352646 | L4: @alexmarin73 | M4: 10Q | N4: 200000 | O4: M15574612 | P4: NEQUI | Q4: JOHANA CASTAÑEDA | R4: ENVIADO | S4: VENCIDO | T4: 46280
A5: 45818.615 | B5: ALEXANDER MARIN CASTAÑEDA | C5: 10018741 | D5: AT116472 | E5: COLOMBIA | F5: RISARALDA | G5: PEREIRA | H5: CLL 86 # 38 A 08 MZ 11 CS 2 | I5: 660001 | J5: almariny@gmail.com | K5: (+57) 3007352646 | L5: @alexmarin73 | M5: 10Q | N5: 200000 | O5: M10446824 | P5: NEQUI | Q5: JOHANA CASTAÑEDA | R5: ENVIADO | S5: VENCIDO | T5: 46280
A6: 45824.615 | B6: ALEXANDER MARIN CASTAÑEDA | C6: 10018741 | D6: AT116472 | E6: COLOMBIA | F6: RISARALDA | G6: PEREIRA | H6: CLL 86 # 38 A 08 MZ 11 CS 2 | I6: 660001 | J6: almariny@gmail.com | K6: (+57) 3007352646 | L6: @alexmarin73 | M6: 10Q | N6: 200000 | O6: M9579646 | P6: NEQUI | Q6: JOHANA CASTAÑEDA | R6: ENVIADO | S6: VENCIDO | T6: 46280
A7: 45831.615 | B7: ALEXANDER MARIN CASTAÑEDA | C7: 10018741 | D7: AT116472 | E7: COLOMBIA | F7: RISARALDA | G7: PEREIRA | H7: CLL 86 # 38 A 08 MZ 11 CS 2 | I7: 660001 | J7: almariny@gmail.com | K7: (+57) 3007352646 | L7: @alexmarin73 | M7: 10Q | N7: 200000 | O7: M8828857 | P7: NEQUI | Q7: JOHANA CASTAÑEDA | R7: ENVIADO | S7: VENCIDO | T7: 46280
A8: 45836.615 | B8: ALEXANDER MARIN CASTAÑEDA | C8: 10018741 | D8: AT116472 | E8: COLOMBIA | F8: RISARALDA | G8: PEREIRA | H8: CLL 86 # 38 A 08 MZ 11 CS 2 | I8: 660001 | J8: almariny@gmail.com | K8: (+57) 3007352646 | L8: @alexmarin73 | M8: 5Q | N8: 500000 | O8: M11116688 | P8: NEQUI | Q8: JOHANA CASTAÑEDA | R8: ENVIADO | S8: VENCIDO | T8: 46280
A9: 45850 | B9: ALEXANDER MARIN CASTAÑEDA | C9: 10018741 | D9: AT116472 | E9: COLOMBIA | F9: RISARALDA | G9: PEREIRA | H9: CLL 86 # 38 A 08 MZ 11 CS 2 | I9: 660001 | J9: almariny@gmail.com | K9: (+57) 3007352646 | L9: @alexmarin73 | M9: 2Q+5N+2V | N9: 300000 | O9: M15993509 | P9: NEQUI | Q9: JOHANA CASTAÑEDA | R9: ENVIADO | S9: VENCIDO | T9: 46280
A10: 45889 | B10: ALEXANDER MARIN CASTAÑEDA | C10: 10018741 | D10: AT116472 | E10: COLOMBIA | F10: RISARALDA | G10: PEREIRA | H10: CLL 86 # 38 A 08 MZ 11 CS 2 | I10: 660001 | J10: almariny@gmail.com | K10: (+57) 3007352646 | L10: @alexmarin73 | M10: 4Q+5N+2V | N10: 200000 | O10: M13915153 | P10: NEQUI | Q10: JOHANA CASTAÑEDA | R10: ENVIADO | S10: VENCIDO | T10: 46280
A11: 45972 | B11: ALEXANDER MARIN CASTAÑEDA | C11: 10018741 | D11: AT116472 | E11: COLOMBIA | F11: RISARALDA | G11: PEREIRA | H11: CLL 86 # 38 A 08 MZ 11 CS 2 | I11: 660001 | J11: almariny@gmail.com | K11: (+57) 3007352646 | L11: @alexmarin73 | M11: COMODIN | N11: 100000 | O11: M06652822 | P11: NEQUI | Q11: JOHANA CASTAÑEDA | R11: ENVIADO | S11: VENCIDO | T11: 46280
A12: 45998 | B12: ALEXANDER MARIN CASTAÑEDA | C12: 10018741 | D12: AT116472 | E12: COLOMBIA | F12: RISARALDA | G12: PEREIRA | H12: CLL 86 # 38 A 08 MZ 11 CS 2 | I12: 660001 | J12: almariny@gmail.com | K12: (+57) 3007352646 | L12: @alexmarin73 | M12: COMODÍN | N12: 100000 | O12: M10128570 | P12: NEQUI | Q12: JOHANA CASTAÑEDA | R12: ENVIADO | S12: VENCIDO | T12: 46280
A13: 46014 | B13: ALEXANDER MARIN CASTAÑEDA | C13: 10018741 | D13: AT116472 | E13: COLOMBIA | F13: RISARALDA | G13: PEREIRA | H13: CLL 86 # 38 A 08 MZ 11 CS 2 | I13: 660001 | J13: almariny@gmail.com | K13: (+57) 3007352646 | L13: @alexmarin73 | M13: // | N13: 100000 | O13: M20655483 | P13: NEQUI | Q13: JOHANA CASTAÑEDA | R13: ENVIADO | S13: VENCIDO | T13: 46280
A14: 46049 | B14: ALEXANDER MARIN CASTAÑEDA | C14: 10018741 | D14: AT116472 | E14: COLOMBIA | F14: RISARALDA | G14: PEREIRA | H14: CLL 86 # 38 A 08 MZ 11 CS 2 | I14: 660001 | J14: almariny@gmail.com | K14: (+57) 3007352646 | L14: @alexmarin73 | M14: 1ZIMCOIN | N14: 500000 | O14: M05036639 | P14: NEQUI | Q14: JOHANA CASTAÑEDA | R14: ENVIADO | S14: VENCIDO | T14: 46280
A15: 46053 | B15: ALEXANDER MARIN CASTAÑEDA | C15: 10018741 | D15: AT116472 | E15: COLOMBIA | F15: RISARALDA | G15: PEREIRA | H15: CLL 86 # 38 A 08 MZ 11 CS 2 | I15: 660001 | J15: almariny@gmail.com | K15: (+57) 3007352646 | L15: @alexmarin73 | M15: 12Q | N15: 300000 | O15: M06363620 | P15: NEQUI | Q15: JOHANA CASTAÑEDA | R15: ENVIADO | S15: VENCIDO | T15: 46280
A16: 46014 | B16: ALIDA FRANCY OVIEDO LOZADA | C16: 55179153 | D16: BH590607 | E16: COLOMBIA | F16: HUILA | G16: NEIVA | H16: CL 7 # 1D – 104 | I16: 410001 | J16: frjuteamo@gmail.com | K16: (+57) 3112441923 | L16: @Francy8576 | M16: 10Q+5N+2V | N16: 400000 | O16: M16502846 | P16: NEQUI | Q16: JOHANA CASTAÑEDA | R16: ENVIADO | S16: VIGENTE
A17: 46128 | B17: ANA BEATRIZ CARIAS PINO | C17: 7148008 | D17: N/A | E17: COLOMBIA | F17: RISARALDA | G17: PEREIRA | H17: CL 73 KR 37 – 26 CASA 46 PISO 1 | I17: 660006 | J17: beaaj17@gmail.com | K17: (+57) 3136229468 | L17: @Karia1728 | M17: 1Q | N17: 0 | O17: GIRO RULETA | P17: N/A | Q17: JOHANA CASTAÑEDA | R17: ENVIADO | S17: N/A
A18: 46128 | B18: ANA BEATRIZ CARIAS PINO | C18: 7148008 | D18: N/A | E18: COLOMBIA | F18: RISARALDA | G18: PEREIRA | H18: CL 73 KR 37 – 26 CASA 46 PISO 1 | I18: 660006 | J18: beaaj17@gmail.com | K18: (+57) 3136229468 | L18: @Karia1728 | M18: 2Q | N18: 100000 | O18: M07700283 | P18: NEQUI | Q18: JOHANA CASTAÑEDA | R18: ENVIADO | S18: N/A
A19: 45832.522 | B19: ANA ISABEL VALENCIA MESA | C19: 41927246 | D19: AX328658 | E19: COLOMBIA | F19: QUINDIO | G19: SALENTO | H19: BARRIO ALDEA ARTESANO BLQ A C 201 | I19: 631028 | J19: anavalenciamesa50@gmail.com | K19: (+57) 3113718240 | L19: @Anais50 | M19: 5Q | N19: 120000 | O19: M2441966 | P19: NEQUI | Q19: JOHANA CASTAÑEDA | R19: ENVIADO | S19: VIGENTE
A20: 45856 | B20: ANAYIBER CARVAJAL CESPEDES | C20: 24587181 | D20: AT403520 | E20: COLOMBIA | F20: RISARALDA | G20: PEREIRA | H20: MNZ 16 CS 11 POBLADO II | I20: 660004 | J20: acarvajal077@gmail.com | K20: (+57) 3147530129 | L20: @CELESTIALJC | M20: 2Q+2N | N20: 200000 | O20: 0000099756 | P20: BANCOLOMBIA | Q20: JOHANA CASTAÑEDA | R20: ENVIADO | S20: VIGENTE | T20: 46365
A21: 45891 | B21: ANDRES MAURICIO MURILLO BALLESTEROS | C21: 75079176 | D21: N/A | E21: COLOMBIA | F21: CALDAS | G21: SALAMINA | H21: CALLE 3 NÚMERO 8-42 | I21: 172001 | J21: maomu2@yahoo.es | K21: (+57) 3218075324 | L21: SIN REGISTRO | M21: 2Q+3N | N21: 300000 | O21: 20431 | P21: DAVIVIENDA | Q21: JOHANA CASTAÑEDA | R21: ENVIADO | S21: N/A
A22: 46003 | B22: ANGEL ALCIDES PAZMIÑO VASCONEZ | C22: 1802036838 | D22: B0083917 | E22: ECUADOR | F22: GUAYAS | G22: MILAGRO | H22: ARIJANGO JIMENEZ 5-45-5 O ENRIQUE ESPIII | I22: 091701 | J22: angelpazminos1965@gmail.com | K22: (+593) 969528889 | L22: @pazmino17 | M22: 2Q | N22: 100000 | O22: M23064602 | P22: NEQUI | Q22: JOHANA CASTAÑEDA | R22: ENVIADO | S22: VIGENTE
A23: 45714.695 | B23: ANGEL RAMIRO TRUJILLO TRUJILLO | C23: 98146902 | D23: N/A | E23: COLOMBIA | F23: NARIÑO | G23: LINARES | H23: LINARES | I23: 526040 | J23: angel3136538260@gmail.com | K23: (+57) 3177801277 | L23: SIN REGISTRO | M23: 1Q | N23: 100000 | O23: 056625 | P23: REDEBAN | Q23: JOHANA CASTAÑEDA | R23: ENVIADO | S23: N/A
A24: 45763.695 | B24: ANGEL RAMIRO TRUJILLO TRUJILLO | C24: 98146902 | D24: N/A | E24: COLOMBIA | F24: NARIÑO | G24: LINARES | H24: LINARES | I24: 526040 | J24: angel3136538260@gmail.com | K24: (+57) 3177801277 | L24: SIN REGISTRO | M24: 1Q | N24: 120000 | O24: 094218 | P24: REDEBAN | Q24: JOHANA CASTAÑEDA | R24: ENVIADO | S24: N/A
A25: 45822.695 | B25: ANGEL RAMIRO TRUJILLO TRUJILLO | C25: 98146902 | D25: N/A | E25: COLOMBIA | F25: NARIÑO | G25: LINARES | H25: LINARES | I25: 526040 | J25: angel3136538260@gmail.com | K25: (+57) 3177801277 | L25: SIN REGISTRO | M25: 1Q | N25: 120000 | O25: 043430 | P25: REDEBAN | Q25: JOHANA CASTAÑEDA | R25: ENVIADO | S25: N/A
A26: 45853.695 | B26: ANGEL RAMIRO TRUJILLO TRUJILLO | C26: 98146902 | D26: N/A | E26: COLOMBIA | F26: NARIÑO | G26: LINARES | H26: LINARES | I26: 526040 | J26: angel3136538260@gmail.com | K26: (+57) 3177801277 | L26: SIN REGISTRO | M26: 2Q+2N | N26: 220000 | O26: M23228079 | P26: NEQUI | Q26: JOHANA CASTAÑEDA | R26: ENVIADO | S26: N/A
A27: 46056 | B27: ANGEL RAMIRO TRUJILLO TRUJILLO | C27: 98146902 | D27: N/A | E27: COLOMBIA | F27: NARIÑO | G27: LINARES | H27: LINARES | I27: 526040 | J27: angel3136538260@gmail.com | K27: (+57) 3177801277 | L27: SIN REGISTRO | M27: 6Q | N27: 150000 | O27: M08491040 | P27: NEQUI | Q27: JOHANA CASTAÑEDA | R27: ENVIADO | S27: N/A
A28: 45811.811 | B28: ANGELA HILDA CANO RUDAS | C28: 30301760 | D28: BF287115 | E28: COLOMBIA | F28: CALDAS | G28: MANIZALES | H28: CLL 19 KR 39-10 | I28: 170004 | J28: canoangela302@gmail.com | K28: (+57) 3234756614 | L28: @angelacano | M28: 10Q | N28: 200000 | O28: M6713334 | P28: NEQUI | Q28: JOHANA CASTAÑEDA | R28: ENVIADO | S28: VIGENTE
A29: 46118 | B29: ANGELA HILDA CANO RUDAS | C29: 30301760 | D29: BF287115 | E29: COLOMBIA | F29: CALDAS | G29: MANIZALES | H29: CLL 19 KR 39-10 | I29: 170004 | J29: canoangela302@gmail.com | K29: (+57) 3234756614 | L29: @angelacano | M29: 2Q+1V | N29: 100000 | O29: M17843664 | P29: NEQUI | Q29: JOHANA CASTAÑEDA | R29: ENVIADO | S29: VIGENTE
A30: 45817 | B30: ARGEMIRO BETANCUR OSORIO | C30: 9970468 | D30: AY548985 | E30: COLOMBIA | F30: RISARALDA | G30: DOSQUEBRADAS | H30: MZ 3 CASA 35 QUINTAS DE ARAGON | I30: 661001 | J30: argemirobetancur@gmail.com | K30: (+57) 3168072144 | L30: @Jrbetancur | M30: 10Q | N30: 200000 | O30: M15484172 | P30: NEQUI | Q30: JOHANA CASTAÑEDA | R30: ENVIADO | S30: VIGENTE
A31: 46014 | B31: ARGEMIRO BETANCUR OSORIO | C31: 9970468 | D31: AY548985 | E31: COLOMBIA | F31: RISARALDA | G31: DOSQUEBRADAS | H31: MZ 3 CASA 35 QUINTAS DE ARAGON | I31: 661001 | J31: argemirobetancur@gmail.com | K31: (+57) 3168072144 | L31: @Jrbetancur | M31: 4Q | N31: 100000 | O31: M20019425 | P31: NEQUI | Q31: JOHANA CASTAÑEDA | R31: ENVIADO | S31: VIGENTE
A32: 46053 | B32: ARGEMIRO BETANCUR OSORIO | C32: 9970468 | D32: AY548985 | E32: COLOMBIA | F32: RISARALDA | G32: DOSQUEBRADAS | H32: MZ 3 CASA 35 QUINTAS DE ARAGON | I32: 661001 | J32: argemirobetancur@gmail.com | K32: (+57) 3168072144 | L32: @Jrbetancur | M32: 6Q | N32: 150000 | O32: IFAK8SQYO3 | P32: BOLD | Q32: JOHANA CASTAÑEDA | R32: ENVIADO | S32: VIGENTE
A33: 46087 | B33: ARGEMIRO BETANCUR OSORIO | C33: 9970468 | D33: AY548985 | E33: COLOMBIA | F33: RISARALDA | G33: DOSQUEBRADAS | H33: MZ 3 CASA 35 QUINTAS DE ARAGON | I33: 661001 | J33: argemirobetancur@gmail.com | K33: (+57) 3168072144 | L33: @Jrbetancur | M33: 1ZIMCOIN+10Q | N33: 0 | O33: CAPACITACIONES | P33: N/A | Q33: JOHANA CASTAÑEDA | R33: ENVIADO | S33: VIGENTE
A34: 46109 | B34: ARGEMIRO BETANCUR OSORIO | C34: 9970468 | D34: AY548985 | E34: COLOMBIA | F34: RISARALDA | G34: DOSQUEBRADAS | H34: MZ 3 CASA 35 QUINTAS DE ARAGON | I34: 661001 | J34: argemirobetancur@gmail.com | K34: (+57) 3168072144 | L34: @Jrbetancur | M34: 2Q | N34: 100000 | O34: 10277706765592499727670027713162687 | P34: DAVIVIENDA | Q34: JOHANA CASTAÑEDA | R34: ENVIADO | S34: VIGENTE
A35: 46115 | B35: ARGEMIRO BETANCUR OSORIO | C35: 9970468 | D35: AY548985 | E35: COLOMBIA | F35: RISARALDA | G35: DOSQUEBRADAS | H35: MZ 3 CASA 35 QUINTAS DE ARAGON | I35: 661001 | J35: argemirobetancur@gmail.com | K35: (+57) 3168072144 | L35: @Jrbetancur | M35: 2Q+1V | N35: 100000 | O35: M04027622 | P35: NEQUI | Q35: JOHANA CASTAÑEDA | R35: ENVIADO | S35: VIGENTE
A36: 46123 | B36: ARGEMIRO BETANCUR OSORIO | C36: 9970468 | D36: AY548985 | E36: COLOMBIA | F36: RISARALDA | G36: DOSQUEBRADAS | H36: MZ 3 CASA 35 QUINTAS DE ARAGON | I36: 661001 | J36: argemirobetancur@gmail.com | K36: (+57) 3168072144 | L36: @Jrbetancur | M36: 6Q+6N | N36: 500000 | O36: M22551211 | P36: NEQUI | Q36: JOHANA CASTAÑEDA | R36: ENVIADO | S36: VIGENTE
A37: 46124.532 | B37: ARGEMIRO BETANCUR OSORIO | C37: 9970468 | D37: AY548985 | E37: COLOMBIA | F37: RISARALDA | G37: DOSQUEBRADAS | H37: MZ 3 CASA 35 QUINTAS DE ARAGON | I37: 661001 | J37: argemirobetancur@gmail.com | K37: (+57) 3168072144 | L37: @Jrbetancur | M37: 1N | N37: 0 | O37: GIRO RULETA | P37: N/A | Q37: JOHANA CASTAÑEDA | R37: ENVIADO | S37: VIGENTE
A38: 46150 | B38: ARGEMIRO BETANCUR OSORIO | C38: 9970468 | D38: AY548985 | E38: COLOMBIA | F38: RISARALDA | G38: DOSQUEBRADAS | H38: MZ 3 CASA 35 QUINTAS DE ARAGON | I38: 661001 | J38: argemirobetancur@gmail.com | K38: (+57) 3168072144 | L38: @Jrbetancur | M38: 2N | N38: 0 | O38: REFERIDOS | P38: N/A | Q38: JOHANA CASTAÑEDA | R38: ENVIADO | S38: VIGENTE
A39: 46172 | B39: ARGEMIRO BETANCUR OSORIO | C39: 9970468 | D39: AY548985 | E39: COLOMBIA | F39: RISARALDA | G39: DOSQUEBRADAS | H39: MANZANA 3 CASA 36 QUINTAS DE ARAGON PLAYA RICA | I39: 661001 | J39: argemirobetancur@gmail.com | K39: (+57) 3168072144 | L39: @Jrbetancur | M39: 5Q | N39: 100000 | O39: M12360461 | P39: LLAVE DAVIPLATA | Q39: JOHANA CASTAÑEDA | R39: ENVIADO | S39: VIGENTE
A40: 46232 | B40: ARGEMIRO BETANCUR OSORIO | C40: 9970468 | D40: AY548985 | E40: COLOMBIA | F40: RISARALDA | G40: DOSQUEBRADAS | H40: MANZANA 3 CASA 36 QUINTAS DE ARAGON PLAYA RICA | I40: 661001 | J40: argemirobetancur@gmail.com | K40: (+57) 3168072144 | L40: @Jrbetancur | M40: 10Q | N40: 200000 | O40: M23685554 | P40: NEQUI | Q40: JOHANA CASTAÑEDA | R40: ENVIADO | S40: VIGENTE
...

Sheet MATRIZ LISTADO
V3: SI | W3: FIDUCIA
V4: NO | W4: NUBE
C16: LIDER: | D16: JOHANA CASTAÑEDA
B18: CC-ID-DNI | C18: NOMBRE | D18: QUINTILLION 5M | F18: NONGENTILLION 10M | H18: VIGINTILLION 7,5M | J18: MONEDA ZIMBABWE 500k | L18: BILLETE DE ZIMBABWE 12,5M | N18: AGROCHEQUE50M | P18: OTROS | R18: USD | S18: TOTAL -10% | T18: 1% PAGO INICIAL | U18: FIDUCIA | V18: NUBE | W18: SKR SI/NO | X18: FIDUCIA/NUBE | Y18: PORCENTAJES | AB18: TOTAL
A19: LISTA | B19: CC-ID-DNI | C19: NOMBRE | D19: CANT | E19: MONTO | F19: CANT2 | G19: MONTO2 | H19: CANT3 | I19: MONTO3 | J19: CANT4 | K19: MONTO4 | L19: CANT5 | M19: MONTO5 | N19: CANT6 | O19: MONTO6 | P19: CANT7 | Q19: MONTO7 | R19: USD | S19: TOTAL -10% | T19: 1% PAGO INICIAL | U19: % FIDUCIA | V19: % NUBE | W19: SKR SI/NO | X19: FIDUCIA/NUBE | Y19: BANCO | Z19: FIDUCIA | AA19: NUBE | AB19: 100%
A20: 1 | B20: 1088244700 | C20: ALEJANDRA GALLEGO RAMÍREZ | D20: 1 | E20: =(Tabla3[[#This Row],[CANT]]*5000000) -> 5000000 | F20: 1 | G20: =(Tabla3[[#This Row],[CANT2]]*10000000) -> 10000000 | H20: 2 | I20: =(Tabla3[[#This Row],[CANT3]]*7500000) -> 15000000 | R20: =(Tabla3[[#This Row],[MONTO]]+Tabla3[[#This Row],[MONTO2]]+Tabla3[[#This Row],[MONTO3]]+Tabla3[[#This Row],[MONTO4]]+Tabla3[[#This Row],[MONTO5]]+Tabla3[[#This Row],[MONTO6]]+Tabla3[[#This Row],[MONTO7]]) -> 30000000 | S20: =R20-(R20*10%) -> 27000000 | T20: =(S20*1%) -> 270000 | U20: =(Tabla3[[#This Row],[TOTAL -10%]]*Tabla3[[#This Row],[FIDUCIA]]) -> 26730000 | V20: =(Tabla3[[#This Row],[TOTAL -10%]]*Tabla3[[#This Row],[NUBE]]) -> 0 | W20: SI | X20: FIDUCIA | Y20: 0.01 | Z20: 0.99 | AB20: =SUM(Y20:AA20) -> 1 | AC20: =IF(AB20="","",IF(AB20=100%,"OK","ERROR")) -> OK
A21: =(A20+1) -> 2 | B21: 25235412 | C21: ALEJANDRA MARIA BETANCUR OSORIO | D21: 2 | E21: =(Tabla3[[#This Row],[CANT]]*5000000) -> 10000000 | H21: 1 | I21: =(Tabla3[[#This Row],[CANT3]]*7500000) -> 7500000 | R21: =(Tabla3[[#This Row],[MONTO]]+Tabla3[[#This Row],[MONTO2]]+Tabla3[[#This Row],[MONTO3]]+Tabla3[[#This Row],[MONTO4]]+Tabla3[[#This Row],[MONTO5]]+Tabla3[[#This Row],[MONTO6]]+Tabla3[[#This Row],[MONTO7]]) -> 17500000 | S21: =R21-(R21*10%) -> 15750000 | T21: =(S21*1%) -> 157500 | U21: =(Tabla3[[#This Row],[TOTAL -10%]]*Tabla3[[#This Row],[FIDUCIA]]) -> 15592500 | V21: =(Tabla3[[#This Row],[TOTAL -10%]]*Tabla3[[#This Row],[NUBE]]) -> 0 | W21: SI | X21: FIDUCIA | Y21: 0.01 | Z21: 0.99 | AB21: =SUM(Y21:AA21) -> 1 | AC21: =IF(AB21="","",IF(AB21=100%,"OK","ERROR")) -> OK
A22: =(A21+1) -> 3 | B22: 10018741 | C22: ALEXANDER MARIN CASTAÑEDA | D22: 63 | E22: =(Tabla3[[#This Row],[CANT]]*5000000) -> 315000000 | F22: 10 | G22: =(Tabla3[[#This Row],[CANT2]]*10000000) -> 100000000 | H22: 4 | I22: =(Tabla3[[#This Row],[CANT3]]*7500000) -> 30000000 | J22: 1 | K22: =(Tabla3[[#This Row],[CANT4]]*500000) -> 500000 | R22: =(Tabla3[[#This Row],[MONTO]]+Tabla3[[#This Row],[MONTO2]]+Tabla3[[#This Row],[MONTO3]]+Tabla3[[#This Row],[MONTO4]]+Tabla3[[#This Row],[MONTO5]]+Tabla3[[#This Row],[MONTO6]]+Tabla3[[#This Row],[MONTO7]]) -> 445500000 | S22: =R22-(R22*10%) -> 400950000 | T22: =(S22*1%) -> 4009500 | U22: =(Tabla3[[#This Row],[TOTAL -10%]]*Tabla3[[#This Row],[FIDUCIA]]) -> 0 | V22: =(Tabla3[[#This Row],[TOTAL -10%]]*Tabla3[[#This Row],[NUBE]]) -> 396940500 | W22: SI | X22: NUBE | Y22: 0.01 | AA22: 0.99 | AB22: =SUM(Y22:AA22) -> 1 | AC22: =IF(AB22="","",IF(AB22=100%,"OK","ERROR")) -> OK
A23: =(A22+1) -> 4 | B23: 55179153 | C23: ALIDA FRANCY OVIEDO LOZADA | D23: 10 | E23: =(Tabla3[[#This Row],[CANT]]*5000000) -> 50000000 | F23: 5 | G23: =(Tabla3[[#This Row],[CANT2]]*10000000) -> 50000000 | H23: 2 | I23: =(Tabla3[[#This Row],[CANT3]]*7500000) -> 15000000 | R23: =(Tabla3[[#This Row],[MONTO]]+Tabla3[[#This Row],[MONTO2]]+Tabla3[[#This Row],[MONTO3]]+Tabla3[[#This Row],[MONTO4]]+Tabla3[[#This Row],[MONTO5]]+Tabla3[[#This Row],[MONTO6]]+Tabla3[[#This Row],[MONTO7]]) -> 115000000 | S23: =R23-(R23*10%) -> 103500000 | T23: =(S23*1%) -> 1035000 | U23: =(Tabla3[[#This Row],[TOTAL -10%]]*Tabla3[[#This Row],[FIDUCIA]]) -> 0 | V23: =(Tabla3[[#This Row],[TOTAL -10%]]*Tabla3[[#This Row],[NUBE]]) -> 102465000 | W23: SI | X23: NUBE | Y23: 0.01 | AA23: 0.99 | AB23: =SUM(Y23:AA23) -> 1 | AC23: =IF(AB23="","",IF(AB23=100%,"OK","ERROR")) -> OK
A24: =(A23+1) -> 5 | B24: 7148008 | C24: ANA BEATRIZ CARIAS PINO | D24: 3 | E24: =(Tabla3[[#This Row],[CANT]]*5000000) -> 15000000 | R24: =(Tabla3[[#This Row],[MONTO]]+Tabla3[[#This Row],[MONTO2]]+Tabla3[[#This Row],[MONTO3]]+Tabla3[[#This Row],[MONTO4]]+Tabla3[[#This Row],[MONTO5]]+Tabla3[[#This Row],[MONTO6]]+Tabla3[[#This Row],[MONTO7]]) -> 15000000 | S24: =R24-(R24*10%) -> 13500000 | T24: =(S24*1%) -> 135000 | U24: =(Tabla3[[#This Row],[TOTAL -10%]]*Tabla3[[#This Row],[FIDUCIA]]) -> 13365000 | V24: =(Tabla3[[#This Row],[TOTAL -10%]]*Tabla3[[#This Row],[NUBE]]) -> 0 | W24: SI | X24: FIDUCIA | Y24: 0.01 | Z24: 0.99 | AB24: =SUM(Y24:AA24) -> 1 | AC24: =IF(AB24="","",IF(AB24=100%,"OK","ERROR")) -> OK
A25: =(A24+1) -> 6 | B25: 41927246 | C25: ANA ISABEL VALENCIA MESA | D25: 5 | E25: =(Tabla3[[#This Row],[CANT]]*5000000) -> 25000000 | R25: =(Tabla3[[#This Row],[MONTO]]+Tabla3[[#This Row],[MONTO2]]+Tabla3[[#This Row],[MONTO3]]+Tabla3[[#This Row],[MONTO4]]+Tabla3[[#This Row],[MONTO5]]+Tabla3[[#This Row],[MONTO6]]+Tabla3[[#This Row],[MONTO7]]) -> 25000000 | S25: =R25-(R25*10%) -> 22500000 | T25: =(S25*1%) -> 225000 | U25: =(Tabla3[[#This Row],[TOTAL -10%]]*Tabla3[[#This Row],[FIDUCIA]]) -> 0 | V25: =(Tabla3[[#This Row],[TOTAL -10%]]*Tabla3[[#This Row],[NUBE]]) -> 22275000 | W25: SI | X25: NUBE | Y25: 0.01 | AA25: 0.99 | AB25: =SUM(Y25:AA25) -> 1 | AC25: =IF(AB25="","",IF(AB25=100%,"OK","ERROR")) -> OK
A26: =(A25+1) -> 7 | B26: 24587181 | C26: ANAYIBER CARVAJAL CESPEDES | D26: 2 | E26: =(Tabla3[[#This Row],[CANT]]*5000000) -> 10000000 | F26: 2 | G26: =(Tabla3[[#This Row],[CANT2]]*10000000) -> 20000000 | R26: =(Tabla3[[#This Row],[MONTO]]+Tabla3[[#This Row],[MONTO2]]+Tabla3[[#This Row],[MONTO3]]+Tabla3[[#This Row],[MONTO4]]+Tabla3[[#This Row],[MONTO5]]+Tabla3[[#This Row],[MONTO6]]+Tabla3[[#This Row],[MONTO7]]) -> 30000000 | S26: =R26-(R26*10%) -> 27000000 | T26: =(S26*1%) -> 270000 | U26: =(Tabla3[[#This Row],[TOTAL -10%]]*Tabla3[[#This Row],[FIDUCIA]]) -> 0 | V26: =(Tabla3[[#This Row],[TOTAL -10%]]*Tabla3[[#This Row],[NUBE]]) -> 26730000 | W26: SI | X26: NUBE | Y26: 0.01 | AA26: 0.99 | AB26: =SUM(Y26:AA26) -> 1 | AC26: =IF(AB26="","",IF(AB26=100%,"OK","ERROR")) -> OK
A27: =(A26+1) -> 8 | B27: 75070176 | C27: ANDRES MAURICIO MURILLO BALLESTEROS | D27: 2 | E27: =(Tabla3[[#This Row],[CANT]]*5000000) -> 10000000 | F27: 3 | G27: =(Tabla3[[#This Row],[CANT2]]*10000000) -> 30000000 | R27: =(Tabla3[[#This Row],[MONTO]]+Tabla3[[#This Row],[MONTO2]]+Tabla3[[#This Row],[MONTO3]]+Tabla3[[#This Row],[MONTO4]]+Tabla3[[#This Row],[MONTO5]]+Tabla3[[#This Row],[MONTO6]]+Tabla3[[#This Row],[MONTO7]]) -> 40000000 | S27: =R27-(R27*10%) -> 36000000 | T27: =(S27*1%) -> 360000 | U27: =(Tabla3[[#This Row],[TOTAL -10%]]*Tabla3[[#This Row],[FIDUCIA]]) -> 35640000 | V27: =(Tabla3[[#This Row],[TOTAL -10%]]*Tabla3[[#This Row],[NUBE]]) -> 0 | W27: SI | X27: FIDUCIA | Y27: 0.01 | Z27: 0.99 | AB27: =SUM(Y27:AA27) -> 1 | AC27: =IF(AB27="","",IF(AB27=100%,"OK","ERROR")) -> OK
A28: =(A27+1) -> 9 | B28: 1802036838 | C28: ANGEL ALCIDES PAZMIÑO VASCONEZ | D28: 2 | E28: =(Tabla3[[#This Row],[CANT]]*5000000) -> 10000000 | R28: =(Tabla3[[#This Row],[MONTO]]+Tabla3[[#This Row],[MONTO2]]+Tabla3[[#This Row],[MONTO3]]+Tabla3[[#This Row],[MONTO4]]+Tabla3[[#This Row],[MONTO5]]+Tabla3[[#This Row],[MONTO6]]+Tabla3[[#This Row],[MONTO7]]) -> 10000000 | S28: =R28-(R28*10%) -> 9000000 | T28: =(S28*1%) -> 90000 | U28: =(Tabla3[[#This Row],[TOTAL -10%]]*Tabla3[[#This Row],[FIDUCIA]]) -> 0 | V28: =(Tabla3[[#This Row],[TOTAL -10%]]*Tabla3[[#This Row],[NUBE]]) -> 8910000 | W28: SI | X28: NUBE | Y28: 0.01 | AA28: 0.99 | AB28: =SUM(Y28:AA28) -> 1 | AC28: =IF(AB28="","",IF(AB28=100%,"OK","ERROR")) -> OK
A29: =(A28+1) -> 10 | B29: 98146902 | C29: ANGEL RAMIRO TRUJILLO TRUJILLO | D29: 11 | E29: =(Tabla3[[#This Row],[CANT]]*5000000) -> 55000000 | F29: 2 | G29: =(Tabla3[[#This Row],[CANT2]]*10000000) -> 20000000 | R29: =(Tabla3[[#This Row],[MONTO]]+Tabla3[[#This Row],[MONTO2]]+Tabla3[[#This Row],[MONTO3]]+Tabla3[[#This Row],[MONTO4]]+Tabla3[[#This Row],[MONTO5]]+Tabla3[[#This Row],[MONTO6]]+Tabla3[[#This Row],[MONTO7]]) -> 75000000 | S29: =R29-(R29*10%) -> 67500000 | T29: =(S29*1%) -> 675000 | U29: =(Tabla3[[#This Row],[TOTAL -10%]]*Tabla3[[#This Row],[FIDUCIA]]) -> 0 | V29: =(Tabla3[[#This Row],[TOTAL -10%]]*Tabla3[[#This Row],[NUBE]]) -> 66825000 | W29: SI | X29: FIDUCIA | Y29: 0.01 | AA29: 0.99 | AB29: =SUM(Y29:AA29) -> 1 | AC29: =IF(AB29="","",IF(AB29=100%,"OK","ERROR")) -> OK
A30: =(A28+1) -> 10 | B30: 30301760 | C30: ANGELA HILDA CANO RUDAS | D30: 12 | E30: =(Tabla3[[#This Row],[CANT]]*5000000) -> 60000000 | H30: 1 | I30: =(Tabla3[[#This Row],[CANT3]]*7500000) -> 7500000 | R30: =(Tabla3[[#This Row],[MONTO]]+Tabla3[[#This Row],[MONTO2]]+Tabla3[[#This Row],[MONTO3]]+Tabla3[[#This Row],[MONTO4]]+Tabla3[[#This Row],[MONTO5]]+Tabla3[[#This Row],[MONTO6]]+Tabla3[[#This Row],[MONTO7]]) -> 67500000 | S30: =R30-(R30*10%) -> 60750000 | T30: =(S30*1%) -> 607500 | U30: =(Tabla3[[#This Row],[TOTAL -10%]]*Tabla3[[#This Row],[FIDUCIA]]) -> 0 | V30: =(Tabla3[[#This Row],[TOTAL -10%]]*Tabla3[[#This Row],[NUBE]]) -> 60142500 | W30: SI | X30: NUBE | Y30: 0.01 | AA30: 0.99 | AB30: =SUM(Y30:AA30) -> 1 | AC30: =IF(AB30="","",IF(AB30=100%,"OK","ERROR")) -> OK
A31: =(A30+1) -> 11 | B31: 9970468 | C31: ARGEMIRO BETANCUR OSORIO | D31: 64 | E31: =(Tabla3[[#This Row],[CANT]]*5000000) -> 320000000 | F31: 8 | G31: =(Tabla3[[#This Row],[CANT2]]*10000000) -> 80000000 | H31: 1 | I31: =(Tabla3[[#This Row],[CANT3]]*7500000) -> 7500000 | J31: 1 | K31: =(Tabla3[[#This Row],[CANT4]]*500000) -> 500000 | R31: =(Tabla3[[#This Row],[MONTO]]+Tabla3[[#This Row],[MONTO2]]+Tabla3[[#This Row],[MONTO3]]+Tabla3[[#This Row],[MONTO4]]+Tabla3[[#This Row],[MONTO5]]+Tabla3[[#This Row],[MONTO6]]+Tabla3[[#This Row],[MONTO7]]) -> 408000000 | S31: =R31-(R31*10%) -> 367200000 | T31: =(S31*1%) -> 3672000 | U31: =(Tabla3[[#This Row],[TOTAL -10%]]*Tabla3[[#This Row],[FIDUCIA]]) -> 0 | V31: =(Tabla3[[#This Row],[TOTAL -10%]]*Tabla3[[#This Row],[NUBE]]) -> 363528000 | W31: SI | X31: NUBE | Y31: 0.01 | AA31: 0.99 | AB31: =SUM(Y31:AA31) -> 1 | AC31: =IF(AB31="","",IF(AB31=100%,"OK","ERROR")) -> OK
A32: =(A31+1) -> 12 | B32: 10276687 | C32: BELMER AUGUSTO BETANCUR OSORIO | D32: 20 | E32: =(Tabla3[[#This Row],[CANT]]*5000000) -> 100000000 | F32: 9 | G32: =(Tabla3[[#This Row],[CANT2]]*10000000) -> 90000000 | H32: 5 | I32: =(Tabla3[[#This Row],[CANT3]]*7500000) -> 37500000 | R32: =(Tabla3[[#This Row],[MONTO]]+Tabla3[[#This Row],[MONTO2]]+Tabla3[[#This Row],[MONTO3]]+Tabla3[[#This Row],[MONTO4]]+Tabla3[[#This Row],[MONTO5]]+Tabla3[[#This Row],[MONTO6]]+Tabla3[[#This Row],[MONTO7]]) -> 227500000 | S32: =R32-(R32*10%) -> 204750000 | T32: =(S32*1%) -> 2047500 | U32: =(Tabla3[[#This Row],[TOTAL -10%]]*Tabla3[[#This Row],[FIDUCIA]]) -> 202702500 | V32: =(Tabla3[[#This Row],[TOTAL -10%]]*Tabla3[[#This Row],[NUBE]]) -> 0 | W32: SI | X32: FIDUCIA | Y32: 0.01 | Z32: 0.99 | AB32: =SUM(Y32:AA32) -> 1 | AC32: =IF(AB32="","",IF(AB32=100%,"OK","ERROR")) -> OK
A33: =(A32+1) -> 13 | B33: 24246828 | C33: BLANCA LUCIA CASTRO GOMEZ | D33: 99 | E33: =(Tabla3[[#This Row],[CANT]]*5000000) -> 495000000 | F33: 16 | G33: =(Tabla3[[#This Row],[CANT2]]*10000000) -> 160000000 | H33: 9 | I33: =(Tabla3[[#This Row],[CANT3]]*7500000) -> 67500000 | J33: 2 | K33: =(Tabla3[[#This Row],[CANT4]]*500000) -> 1000000 | N33: 1 | O33: =(Tabla3[[#This Row],[CANT6]]*200000) -> 200000 | R33: =(Tabla3[[#This Row],[MONTO]]+Tabla3[[#This Row],[MONTO2]]+Tabla3[[#This Row],[MONTO3]]+Tabla3[[#This Row],[MONTO4]]+Tabla3[[#This Row],[MONTO5]]+Tabla3[[#This Row],[MONTO6]]+Tabla3[[#This Row],[MONTO7]]) -> 723700000 | S33: =R33-(R33*10%) -> 651330000 | T33: =(S33*1%) -> 6513300 | U33: =(Tabla3[[#This Row],[TOTAL -10%]]*Tabla3[[#This Row],[FIDUCIA]]) -> 0 | V33: =(Tabla3[[#This Row],[TOTAL -10%]]*Tabla3[[#This Row],[NUBE]]) -> 644816700 | W33: SI | X33: NUBE | Y33: 0.01 | AA33: 0.99 | AB33: =SUM(Y33:AA33) -> 1 | AC33: =IF(AB33="","",IF(AB33=100%,"OK","ERROR")) -> OK
A34: =(A33+1) -> 14 | B34: 1004773723 | C34: CARLOS ALEJANDRO FLOR TAQUEZ | D34: 1 | E34: =(Tabla3[[#This Row],[CANT]]*5000000) -> 5000000 | F34: 1 | G34: =(Tabla3[[#This Row],[CANT2]]*10000000) -> 10000000 | H34: 2 | I34: =(Tabla3[[#This Row],[CANT3]]*7500000) -> 15000000 | R34: =(Tabla3[[#This Row],[MONTO]]+Tabla3[[#This Row],[MONTO2]]+Tabla3[[#This Row],[MONTO3]]+Tabla3[[#This Row],[MONTO4]]+Tabla3[[#This Row],[MONTO5]]+Tabla3[[#This Row],[MONTO6]]+Tabla3[[#This Row],[MONTO7]]) -> 30000000 | S34: =R34-(R34*10%) -> 27000000 | T34: =(S34*1%) -> 270000 | U34: =(Tabla3[[#This Row],[TOTAL -10%]]*Tabla3[[#This Row],[FIDUCIA]]) -> 26730000 | V34: =(Tabla3[[#This Row],[TOTAL -10%]]*Tabla3[[#This Row],[NUBE]]) -> 0 | W34: SI | X34: FIDUCIA | Y34: 0.01 | Z34: 0.99 | AB34: =SUM(Y34:AA34) -> 1 | AC34: =IF(AB34="","",IF(AB34=100%,"OK","ERROR")) -> OK
A35: =(A34+1) -> 15 | B35: 13079041 | C35: CARLOS FLOR CORDOBA | D35: 2 | E35: =(Tabla3[[#This Row],[CANT]]*5000000) -> 10000000 | F35: 3 | G35: =(Tabla3[[#This Row],[CANT2]]*10000000) -> 30000000 | H35: 2 | I35: =(Tabla3[[#This Row],[CANT3]]*7500000) -> 15000000 | R35: =(Tabla3[[#This Row],[MONTO]]+Tabla3[[#This Row],[MONTO2]]+Tabla3[[#This Row],[MONTO3]]+Tabla3[[#This Row],[MONTO4]]+Tabla3[[#This Row],[MONTO5]]+Tabla3[[#This Row],[MONTO6]]+Tabla3[[#This Row],[MONTO7]]) -> 55000000 | S35: =R35-(R35*10%) -> 49500000 | T35: =(S35*1%) -> 495000 | U35: =(Tabla3[[#This Row],[TOTAL -10%]]*Tabla3[[#This Row],[FIDUCIA]]) -> 49005000 | V35: =(Tabla3[[#This Row],[TOTAL -10%]]*Tabla3[[#This Row],[NUBE]]) -> 0 | W35: SI | X35: FIDUCIA | Y35: 0.01 | Z35: 0.99 | AB35: =SUM(Y35:AA35) -> 1 | AC35: =IF(AB35="","",IF(AB35=100%,"OK","ERROR")) -> OK
A36: =(A35+1) -> 16 | B36: 75060017 | C36: CARLOS HUBERTO GONZALEZ OCAMPO | D36: 8 | E36: =(Tabla3[[#This Row],[CANT]]*5000000) -> 40000000 | F36: 3 | G36: =(Tabla3[[#This Row],[CANT2]]*10000000) -> 30000000 | R36: =(Tabla3[[#This Row],[MONTO]]+Tabla3[[#This Row],[MONTO2]]+Tabla3[[#This Row],[MONTO3]]+Tabla3[[#This Row],[MONTO4]]+Tabla3[[#This Row],[MONTO5]]+Tabla3[[#This Row],[MONTO6]]+Tabla3[[#This Row],[MONTO7]]) -> 70000000 | S36: =R36-(R36*10%) -> 63000000 | T36: =(S36*1%) -> 630000 | U36: =(Tabla3[[#This Row],[TOTAL -10%]]*Tabla3[[#This Row],[FIDUCIA]]) -> 62370000 | V36: =(Tabla3[[#This Row],[TOTAL -10%]]*Tabla3[[#This Row],[NUBE]]) -> 0 | W36: SI | X36: FIDUCIA | Y36: 0.01 | Z36: 0.99 | AB36: =SUM(Y36:AA36) -> 1 | AC36: =IF(AB36="","",IF(AB36=100%,"OK","ERROR")) -> OK
A37: =(A36+1) -> 17 | B37: 42085517 | C37: CARMEN ADRIANA CASTAÑO CORREA | D37: 17 | E37: =(Tabla3[[#This Row],[CANT]]*5000000) -> 85000000 | F37: 15 | G37: =(Tabla3[[#This Row],[CANT2]]*10000000) -> 150000000 | H37: 3 | I37: =(Tabla3[[#This Row],[CANT3]]*7500000) -> 22500000 | R37: =(Tabla3[[#This Row],[MONTO]]+Tabla3[[#This Row],[MONTO2]]+Tabla3[[#This Row],[MONTO3]]+Tabla3[[#This Row],[MONTO4]]+Tabla3[[#This Row],[MONTO5]]+Tabla3[[#This Row],[MONTO6]]+Tabla3[[#This Row],[MONTO7]]) -> 257500000 | S37: =R37-(R37*10%) -> 231750000 | T37: =(S37*1%) -> 2317500 | U37: =(Tabla3[[#This Row],[TOTAL -10%]]*Tabla3[[#This Row],[FIDUCIA]]) -> 0 | V37: =(Tabla3[[#This Row],[TOTAL -10%]]*Tabla3[[#This Row],[NUBE]]) -> 229432500 | W37: SI | X37: NUBE | Y37: 0.01 | AA37: 0.99 | AB37: =SUM(Y37:AA37) -> 1 | AC37: =IF(AB37="","",IF(AB37=100%,"OK","ERROR")) -> OK
A38: =(A37+1) -> 18 | B38: 4612227 | C38: CELSO NEL ORTEGA CAMPO | D38: 2 | E38: =(Tabla3[[#This Row],[CANT]]*5000000) -> 10000000 | R38: =(Tabla3[[#This Row],[MONTO]]+Tabla3[[#This Row],[MONTO2]]+Tabla3[[#This Row],[MONTO3]]+Tabla3[[#This Row],[MONTO4]]+Tabla3[[#This Row],[MONTO5]]+Tabla3[[#This Row],[MONTO6]]+Tabla3[[#This Row],[MONTO7]]) -> 10000000 | S38: =R38-(R38*10%) -> 9000000 | T38: =(S38*1%) -> 90000 | U38: =(Tabla3[[#This Row],[TOTAL -10%]]*Tabla3[[#This Row],[FIDUCIA]]) -> 0 | V38: =(Tabla3[[#This Row],[TOTAL -10%]]*Tabla3[[#This Row],[NUBE]]) -> 8910000 | W38: SI | X38: NUBE | Y38: 0.01 | AA38: 0.99 | AB38: =SUM(Y38:AA38) -> 1 | AC38: =IF(AB38="","",IF(AB38=100%,"OK","ERROR")) -> OK
A39: =(A38+1) -> 19 | B39: 42081364 | C39: CLAUDIA CRISTINA CASTAÑO CORREA | D39: 24 | E39: =(Tabla3[[#This Row],[CANT]]*5000000) -> 120000000 | F39: 19 | G39: =(Tabla3[[#This Row],[CANT2]]*10000000) -> 190000000 | H39: 6 | I39: =(Tabla3[[#This Row],[CANT3]]*7500000) -> 45000000 | R39: =(Tabla3[[#This Row],[MONTO]]+Tabla3[[#This Row],[MONTO2]]+Tabla3[[#This Row],[MONTO3]]+Tabla3[[#This Row],[MONTO4]]+Tabla3[[#This Row],[MONTO5]]+Tabla3[[#This Row],[MONTO6]]+Tabla3[[#This Row],[MONTO7]]) -> 355000000 | S39: =R39-(R39*10%) -> 319500000 | T39: =(S39*1%) -> 3195000 | U39: =(Tabla3[[#This Row],[TOTAL -10%]]*Tabla3[[#This Row],[FIDUCIA]]) -> 0 | V39: =(Tabla3[[#This Row],[TOTAL -10%]]*Tabla3[[#This Row],[NUBE]]) -> 316305000 | W39: SI | X39: NUBE | Y39: 0.01 | AA39: 0.99 | AB39: =SUM(Y39:AA39) -> 1 | AC39: =IF(AB39="","",IF(AB39=100%,"OK","ERROR")) -> OK
A40: =(A39+1) -> 20 | B40: 34566045 | C40: CLAUDIA ESTELA LOPEZ CAMACHO | D40: 11 | E40: =(Tabla3[[#This Row],[CANT]]*5000000) -> 55000000 | F40: 15 | G40: =(Tabla3[[#This Row],[CANT2]]*10000000) -> 150000000 | H40: 10 | I40: =(Tabla3[[#This Row],[CANT3]]*7500000) -> 75000000 | J40: 3 | K40: =(Tabla3[[#This Row],[CANT4]]*500000) -> 1500000 | R40: =(Tabla3[[#This Row],[MONTO]]+Tabla3[[#This Row],[MONTO2]]+Tabla3[[#This Row],[MONTO3]]+Tabla3[[#This Row],[MONTO4]]+Tabla3[[#This Row],[MONTO5]]+Tabla3[[#This Row],[MONTO6]]+Tabla3[[#This Row],[MONTO7]]) -> 281500000 | S40: =R40-(R40*10%) -> 253350000 | T40: =(S40*1%) -> 2533500 | U40: =(Tabla3[[#This Row],[TOTAL -10%]]*Tabla3[[#This Row],[FIDUCIA]]) -> 0 | V40: =(Tabla3[[#This Row],[TOTAL -10%]]*Tabla3[[#This Row],[NUBE]]) -> 250816500 | W40: SI | X40: NUBE | Y40: 0.01 | AA40: 0.99 | AB40: =SUM(Y40:AA40) -> 1 | AC40: =IF(AB40="","",IF(AB40=100%,"OK","ERROR")) -> OK
A41: =(A40+1) -> 21 | B41: 30337930 | C41: CLAUDIA MARCELA MARULANDA GIRALDO | D41: 2 | E41: =(Tabla3[[#This Row],[CANT]]*5000000) -> 10000000 | F41: 3 | G41: =(Tabla3[[#This Row],[CANT2]]*10000000) -> 30000000 | H41: 2 | I41: =(Tabla3[[#This Row],[CANT3]]*7500000) -> 15000000 | R41: =(Tabla3[[#This Row],[MONTO]]+Tabla3[[#This Row],[MONTO2]]+Tabla3[[#This Row],[MONTO3]]+Tabla3[[#This Row],[MONTO4]]+Tabla3[[#This Row],[MONTO5]]+Tabla3[[#This Row],[MONTO6]]+Tabla3[[#This Row],[MONTO7]]) -> 55000000 | S41: =R41-(R41*10%) -> 49500000 | T41: =(S41*1%) -> 495000 | U41: =(Tabla3[[#This Row],[TOTAL -10%]]*Tabla3[[#This Row],[FIDUCIA]]) -> 49005000 | V41: =(Tabla3[[#This Row],[TOTAL -10%]]*Tabla3[[#This Row],[NUBE]]) -> 0 | W41: SI | X41: FIDUCIA | Y41: 0.01 | Z41: 0.99 | AB41: =SUM(Y41:AA41) -> 1 | AC41: =IF(AB41="","",IF(AB41=100%,"OK","ERROR")) -> OK
A42: =(A41+1) -> 22 | B42: 1053860357 | C42: CRISTIAN DAVID HERRERA MARÍN | D42: 2 | E42: =(Tabla3[[#This Row],[CANT]]*5000000) -> 10000000 | H42: 1 | I42: =(Tabla3[[#This Row],[CANT3]]*7500000) -> 7500000 | R42: =(Tabla3[[#This Row],[MONTO]]+Tabla3[[#This Row],[MONTO2]]+Tabla3[[#This Row],[MONTO3]]+Tabla3[[#This Row],[MONTO4]]+Tabla3[[#This Row],[MONTO5]]+Tabla3[[#This Row],[MONTO6]]+Tabla3[[#This Row],[MONTO7]]) -> 17500000 | S42: =R42-(R42*10%) -> 15750000 | T42: =(S42*1%) -> 157500 | U42: =(Tabla3[[#This Row],[TOTAL -10%]]*Tabla3[[#This Row],[FIDUCIA]]) -> 0 | V42: =(Tabla3[[#This Row],[TOTAL -10%]]*Tabla3[[#This Row],[NUBE]]) -> 15592500 | W42: SI | X42: NUBE | Y42: 0.01 | AA42: 0.99 | AB42: =SUM(Y42:AA42) -> 1 | AC42: =IF(AB42="","",IF(AB42=100%,"OK","ERROR")) -> OK
A43: =(A42+1) -> 23 | B43: 38847495 | C43: CRISTIAN ESTEBAN LEZCANO | D43: 20 | E43: =(Tabla3[[#This Row],[CANT]]*5000000) -> 100000000 | R43: =(Tabla3[[#This Row],[MONTO]]+Tabla3[[#This Row],[MONTO2]]+Tabla3[[#This Row],[MONTO3]]+Tabla3[[#This Row],[MONTO4]]+Tabla3[[#This Row],[MONTO5]]+Tabla3[[#This Row],[MONTO6]]+Tabla3[[#This Row],[MONTO7]]) -> 100000000 | S43: =R43-(R43*10%) -> 90000000 | T43: =(S43*1%) -> 900000 | U43: =(Tabla3[[#This Row],[TOTAL -10%]]*Tabla3[[#This Row],[FIDUCIA]]) -> 0 | V43: =(Tabla3[[#This Row],[TOTAL -10%]]*Tabla3[[#This Row],[NUBE]]) -> 89100000 | W43: SI | X43: NUBE | Y43: 0.01 | AA43: 0.99 | AB43: =SUM(Y43:AA43) -> 1 | AC43: =IF(AB43="","",IF(AB43=100%,"OK","ERROR")) -> OK
A44: =(A43+1) -> 24 | B44: 40369286 | C44: DELIA MARIA REY ACOSTA | D44: 5 | E44: =(Tabla3[[#This Row],[CANT]]*5000000) -> 25000000 | R44: =(Tabla3[[#This Row],[MONTO]]+Tabla3[[#This Row],[MONTO2]]+Tabla3[[#This Row],[MONTO3]]+Tabla3[[#This Row],[MONTO4]]+Tabla3[[#This Row],[MONTO5]]+Tabla3[[#This Row],[MONTO6]]+Tabla3[[#This Row],[MONTO7]]) -> 25000000 | S44: =R44-(R44*10%) -> 22500000 | T44: =(S44*1%) -> 225000 | U44: =(Tabla3[[#This Row],[TOTAL -10%]]*Tabla3[[#This Row],[FIDUCIA]]) -> 22275000 | V44: =(Tabla3[[#This Row],[TOTAL -10%]]*Tabla3[[#This Row],[NUBE]]) -> 0 | W44: SI | X44: FIDUCIA | Y44: 0.01 | Z44: 0.99 | AB44: =SUM(Y44:AA44) -> 1 | AC44: =IF(AB44="","",IF(AB44=100%,"OK","ERROR")) -> OK
A45: =(A44+1) -> 25 | B45: 43872922 | C45: DIANA MARCELA SANCHEZ MARIN | D45: 4 | E45: =(Tabla3[[#This Row],[CANT]]*5000000) -> 20000000 | F45: 4 | G45: =(Tabla3[[#This Row],[CANT2]]*10000000) -> 40000000 | L45: 1 | M45: =(L45*12500000) -> 12500000 | N45: 1 | O45: =(N45*200000) -> 200000 | R45: =(Tabla3[[#This Row],[MONTO]]+Tabla3[[#This Row],[MONTO2]]+Tabla3[[#This Row],[MONTO3]]+Tabla3[[#This Row],[MONTO4]]+Tabla3[[#This Row],[MONTO5]]+Tabla3[[#This Row],[MONTO6]]+Tabla3[[#This Row],[MONTO7]]) -> 72700000 | S45: =R45-(R45*10%) -> 65430000 | T45: =(S45*1%) -> 654300 | U45: =(Tabla3[[#This Row],[TOTAL -10%]]*Tabla3[[#This Row],[FIDUCIA]]) -> 0 | V45: =(Tabla3[[#This Row],[TOTAL -10%]]*Tabla3[[#This Row],[NUBE]]) -> 64775700 | W45: SI | X45: NUBE | Y45: 0.01 | AA45: 0.99 | AB45: =SUM(Y45:AA45) -> 1 | AC45: =IF(AB45="","",IF(AB45=100%,"OK","ERROR")) -> OK
A46: =(A45+1) -> 26 | B46: 29832605 | C46: DIANA PATRICIA ARBELAEZ FLOREZ | D46: 20 | E46: =(Tabla3[[#This Row],[CANT]]*5000000) -> 100000000 | F46: 12 | G46: =(Tabla3[[#This Row],[CANT2]]*10000000) -> 120000000 | H46: 12 | I46: =(Tabla3[[#This Row],[CANT3]]*7500000) -> 90000000 | L46: 1 | M46: =(L46*12500000) -> 12500000 | R46: =(Tabla3[[#This Row],[MONTO]]+Tabla3[[#This Row],[MONTO2]]+Tabla3[[#This Row],[MONTO3]]+Tabla3[[#This Row],[MONTO4]]+Tabla3[[#This Row],[MONTO5]]+Tabla3[[#This Row],[MONTO6]]+Tabla3[[#This Row],[MONTO7]]) -> 322500000 | S46: =R46-(R46*10%) -> 290250000 | T46: =(S46*1%) -> 2902500 | U46: =(Tabla3[[#This Row],[TOTAL -10%]]*Tabla3[[#This Row],[FIDUCIA]]) -> 0 | V46: =(Tabla3[[#This Row],[TOTAL -10%]]*Tabla3[[#This Row],[NUBE]]) -> 287347500 | W46: SI | X46: NUBE | Y46: 0.01 | AA46: 0.99 | AB46: =SUM(Y46:AA46) -> 1 | AC46: =IF(AB46="","",IF(AB46=100%,"OK","ERROR")) -> OK
A47: =(A46+1) -> 27 | B47: 10298946 | C47: DIEGO FELIPE MAZORRA | D47: 1 | E47: =(Tabla3[[#This Row],[CANT]]*5000000) -> 5000000 | J47: 1 | K47: =(Tabla3[[#This Row],[CANT4]]*500000) -> 500000 | R47: =(Tabla3[[#This Row],[MONTO]]+Tabla3[[#This Row],[MONTO2]]+Tabla3[[#This Row],[MONTO3]]+Tabla3[[#This Row],[MONTO4]]+Tabla3[[#This Row],[MONTO5]]+Tabla3[[#This Row],[MONTO6]]+Tabla3[[#This Row],[MONTO7]]) -> 5500000 | S47: =R47-(R47*10%) -> 4950000 | T47: =(S47*1%) -> 49500 | U47: =(Tabla3[[#This Row],[TOTAL -10%]]*Tabla3[[#This Row],[FIDUCIA]]) -> 4900500 | V47: =(Tabla3[[#This Row],[TOTAL -10%]]*Tabla3[[#This Row],[NUBE]]) -> 0 | W47: SI | X47: FIDUCIA | Y47: 0.01 | Z47: 0.99 | AB47: =SUM(Y47:AA47) -> 1 | AC47: =IF(AB47="","",IF(AB47=100%,"OK","ERROR")) -> OK
A48: =(A47+1) -> 28 | B48: 13700726 | C48: ELIAS SANABRIA MELGAREJO | D48: 37 | E48: =(Tabla3[[#This Row],[CANT]]*5000000) -> 185000000 | F48: 2 | G48: =(Tabla3[[#This Row],[CANT2]]*10000000) -> 20000000 | H48: 1 | I48: =(Tabla3[[#This Row],[CANT3]]*7500000) -> 7500000 | R48: =(Tabla3[[#This Row],[MONTO]]+Tabla3[[#This Row],[MONTO2]]+Tabla3[[#This Row],[MONTO3]]+Tabla3[[#This Row],[MONTO4]]+Tabla3[[#This Row],[MONTO5]]+Tabla3[[#This Row],[MONTO6]]+Tabla3[[#This Row],[MONTO7]]) -> 212500000 | S48: =R48-(R48*10%) -> 191250000 | T48: =(S48*1%) -> 1912500 | U48: =(Tabla3[[#This Row],[TOTAL -10%]]*Tabla3[[#This Row],[FIDUCIA]]) -> 0 | V48: =(Tabla3[[#This Row],[TOTAL -10%]]*Tabla3[[#This Row],[NUBE]]) -> 189337500 | W48: SI | X48: NUBE | Y48: 0.01 | AA48: 0.99 | AB48: =SUM(Y48:AA48) -> 1 | AC48: =IF(AB48="","",IF(AB48=100%,"OK","ERROR")) -> OK
A49: =(A48+1) -> 29 | B49: 30332751 | C49: ELSA PATRICIA MARULANDA GIRALDO | D49: 4 | E49: =(Tabla3[[#This Row],[CANT]]*5000000) -> 20000000 | F49: 3 | G49: =(Tabla3[[#This Row],[CANT2]]*10000000) -> 30000000 | R49: =(Tabla3[[#This Row],[MONTO]]+Tabla3[[#This Row],[MONTO2]]+Tabla3[[#This Row],[MONTO3]]+Tabla3[[#This Row],[MONTO4]]+Tabla3[[#This Row],[MONTO5]]+Tabla3[[#This Row],[MONTO6]]+Tabla3[[#This Row],[MONTO7]]) -> 50000000 | S49: =R49-(R49*10%) -> 45000000 | T49: =(S49*1%) -> 450000 | U49: =(Tabla3[[#This Row],[TOTAL -10%]]*Tabla3[[#This Row],[FIDUCIA]]) -> 44550000 | V49: =(Tabla3[[#This Row],[TOTAL -10%]]*Tabla3[[#This Row],[NUBE]]) -> 0 | W49: SI | X49: FIDUCIA | Y49: 0.01 | Z49: 0.99 | AB49: =SUM(Y49:AA49) -> 1 | AC49: =IF(AB49="","",IF(AB49=100%,"OK","ERROR")) -> OK
A50: =(A49+1) -> 30 | B50: 34553021 | C50: EMILSEN YANGANA OLIVAR | D50: 16 | E50: =(Tabla3[[#This Row],[CANT]]*5000000) -> 80000000 | R50: =(Tabla3[[#This Row],[MONTO]]+Tabla3[[#This Row],[MONTO2]]+Tabla3[[#This Row],[MONTO3]]+Tabla3[[#This Row],[MONTO4]]+Tabla3[[#This Row],[MONTO5]]+Tabla3[[#This Row],[MONTO6]]+Tabla3[[#This Row],[MONTO7]]) -> 80000000 | S50: =R50-(R50*10%) -> 72000000 | T50: =(S50*1%) -> 720000 | U50: =(Tabla3[[#This Row],[TOTAL -10%]]*Tabla3[[#This Row],[FIDUCIA]]) -> 71280000 | V50: =(Tabla3[[#This Row],[TOTAL -10%]]*Tabla3[[#This Row],[NUBE]]) -> 0 | W50: SI | X50: FIDUCIA | Y50: 0.01 | Z50: 0.99 | AB50: =SUM(Y50:AA50) -> 1 | AC50: =IF(AB50="","",IF(AB50=100%,"OK","ERROR")) -> OK
A51: =(A50+1) -> 31 | B51: 43793721 | C51: ERICKA YAMILE VALENCIA GOMEZ | D51: 108 | E51: =(Tabla3[[#This Row],[CANT]]*5000000) -> 540000000 | F51: 5 | G51: =(Tabla3[[#This Row],[CANT2]]*10000000) -> 50000000 | H51: 2 | I51: =(Tabla3[[#This Row],[CANT3]]*7500000) -> 15000000 | J51: 3 | K51: =(Tabla3[[#This Row],[CANT4]]*500000) -> 1500000 | R51: =(Tabla3[[#This Row],[MONTO]]+Tabla3[[#This Row],[MONTO2]]+Tabla3[[#This Row],[MONTO3]]+Tabla3[[#This Row],[MONTO4]]+Tabla3[[#This Row],[MONTO5]]+Tabla3[[#This Row],[MONTO6]]+Tabla3[[#This Row],[MONTO7]]) -> 606500000 | S51: =R51-(R51*10%) -> 545850000 | T51: =(S51*1%) -> 5458500 | U51: =(Tabla3[[#This Row],[TOTAL -10%]]*Tabla3[[#This Row],[FIDUCIA]]) -> 540391500 | V51: =(Tabla3[[#This Row],[TOTAL -10%]]*Tabla3[[#This Row],[NUBE]]) -> 0 | W51: SI | X51: FIDUCIA | Y51: 0.01 | Z51: 0.99 | AB51: =SUM(Y51:AA51) -> 1 | AC51: =IF(AB51="","",IF(AB51=100%,"OK","ERROR")) -> OK
A52: =(A51+1) -> 32 | B52: 1053848679 | C52: ERIK ALEJANDRO CASTAÑEDA CANO | D52: 2 | E52: =(Tabla3[[#This Row],[CANT]]*5000000) -> 10000000 | F52: 5 | G52: =(Tabla3[[#This Row],[CANT2]]*10000000) -> 50000000 | H52: 1 | I52: =(Tabla3[[#This Row],[CANT3]]*7500000) -> 7500000 | R52: =(Tabla3[[#This Row],[MONTO]]+Tabla3[[#This Row],[MONTO2]]+Tabla3[[#This Row],[MONTO3]]+Tabla3[[#This Row],[MONTO4]]+Tabla3[[#This Row],[MONTO5]]+Tabla3[[#This Row],[MONTO6]]+Tabla3[[#This Row],[MONTO7]]) -> 67500000 | S52: =R52-(R52*10%) -> 60750000 | T52: =(S52*1%) -> 607500 | U52: =(Tabla3[[#This Row],[TOTAL -10%]]*Tabla3[[#This Row],[FIDUCIA]]) -> 0 | V52: =(Tabla3[[#This Row],[TOTAL -10%]]*Tabla3[[#This Row],[NUBE]]) -> 60142500 | W52: SI | X52: NUBE | Y52: 0.01 | AA52: 0.99 | AB52: =SUM(Y52:AA52) -> 1 | AC52: =IF(AB52="","",IF(AB52=100%,"OK","ERROR")) -> OK
A53: =(A52+1) -> 33 | B53: 1063812968 | C53: FRANCY YULIANA BOLAÑOS PERAFAN | D53: 4 | E53: =(Tabla3[[#This Row],[CANT]]*5000000) -> 20000000 | F53: 6 | G53: =(Tabla3[[#This Row],[CANT2]]*10000000) -> 60000000 | H53: 4 | I53: =(Tabla3[[#This Row],[CANT3]]*7500000) -> 30000000 | R53: =(Tabla3[[#This Row],[MONTO]]+Tabla3[[#This Row],[MONTO2]]+Tabla3[[#This Row],[MONTO3]]+Tabla3[[#This Row],[MONTO4]]+Tabla3[[#This Row],[MONTO5]]+Tabla3[[#This Row],[MONTO6]]+Tabla3[[#This Row],[MONTO7]]) -> 110000000 | S53: =R53-(R53*10%) -> 99000000 | T53: =(S53*1%) -> 990000 | U53: =(Tabla3[[#This Row],[TOTAL -10%]]*Tabla3[[#This Row],[FIDUCIA]]) -> 98010000 | V53: =(Tabla3[[#This Row],[TOTAL -10%]]*Tabla3[[#This Row],[NUBE]]) -> 0 | W53: SI | X53: FIDUCIA | Y53: 0.01 | Z53: 0.99 | AB53: =SUM(Y53:AA53) -> 1 | AC53: =IF(AB53="","",IF(AB53=100%,"OK","ERROR")) -> OK
A54: =(A53+1) -> 34 | B54: 31423160 | C54: FRANS ORFINDEY GUTIERREZ NOREÑA | D54: 5 | E54: =(Tabla3[[#This Row],[CANT]]*5000000) -> 25000000 | R54: =(Tabla3[[#This Row],[MONTO]]+Tabla3[[#This Row],[MONTO2]]+Tabla3[[#This Row],[MONTO3]]+Tabla3[[#This Row],[MONTO4]]+Tabla3[[#This Row],[MONTO5]]+Tabla3[[#This Row],[MONTO6]]+Tabla3[[#This Row],[MONTO7]]) -> 25000000 | S54: =R54-(R54*10%) -> 22500000 | T54: =(S54*1%) -> 225000 | U54: =(Tabla3[[#This Row],[TOTAL -10%]]*Tabla3[[#This Row],[FIDUCIA]]) -> 0 | V54: =(Tabla3[[#This Row],[TOTAL -10%]]*Tabla3[[#This Row],[NUBE]]) -> 22275000 | W54: SI | X54: NUBE | Y54: 0.01 | AA54: 0.99 | AB54: =SUM(Y54:AA54) -> 1 | AC54: =IF(AB54="","",IF(AB54=100%,"OK","ERROR")) -> OK
...

Sheet RESUMEN INDIVIDUAL
O3: FECHA
O4: =TODAY() -> 46288
E5: LIDER: | F5: =('MATRIZ LISTADO'!D16) -> JOHANA CASTAÑEDA | O5: Consulta con el valor del dólar (TRM) Aquí | Q5: https://www.dolar-colombia.com/
O6: 3072.27
E7: NOMBRE | F7: =IFERROR(VLOOKUP(F8,'MATRIZ LISTADO'!B19:C144,2,0),"") -> JHON JADER OYOLA OSORIO | L7: =(F7) -> JHON JADER OYOLA OSORIO
E8: CC/ID/DNI | F8: 18510129 | L8: PAGO CON DESCUENTOS | P8: PESOS COLOMBIANOS
L9: PAGO TOTAL | O9: -0.1 | P9: =(G28*O6) -> 4017607479000
L10: 0.01 | O10: BANCO | P10: =(I14*O6) -> 40176074790
F11: CANT | G11: PAGO | I11: ORDEN DE PAGOS | L11: =IFERROR(VLOOKUP(F8,'MATRIZ LISTADO'!B19:AA144,25,0),"") -> 0 | O11: FIDUCIA | P11: =(I18*O6) -> 0
E12: QUINTILLION | F12: =IFERROR(VLOOKUP($F$8,Tabla3[[#All],[CC-ID-DNI]:[CANT]],3,0),"") -> 146 | G12: =IFERROR(VLOOKUP($F$8,Tabla3[[#All],[CC-ID-DNI]:[1% PAGO INICIAL]],4,0),"") -> 730000000 | I12: 1% PAGO BANCO | L12: =IFERROR(VLOOKUP(F8,'MATRIZ LISTADO'!B19:AB144,26,0),"") -> 0.99 | O12: NUBE | P12: =(I22*O6) -> 3977431404210
E14: NONGENTILLION | F14: =IFERROR(VLOOKUP($F$8,Tabla3[[CC-ID-DNI]:[1% PAGO INICIAL]],5,0),"") -> 60 | G14: =IFERROR(VLOOKUP($F$8,Tabla3[[#All],[CC-ID-DNI]:[1% PAGO INICIAL]],6,0),"") -> 600000000 | I14: =(G28*1%) -> 13077000
E16: VIGINTILLION | F16: =IFERROR(VLOOKUP($F$8,Tabla3[[CC-ID-DNI]:[1% PAGO INICIAL]],7,0),"") -> 16 | G16: =IFERROR(VLOOKUP($F$8,Tabla3[[#All],[CC-ID-DNI]:[1% PAGO INICIAL]],8,0),"") -> 120000000 | I16: FIDUCIA
E18: MONEDA DE ZIM | F18: =IFERROR(VLOOKUP($F$8,Tabla3[[CC-ID-DNI]:[1% PAGO INICIAL]],9,0),"") -> 6 | G18: =IFERROR(VLOOKUP($F$8,Tabla3[[#All],[CC-ID-DNI]:[1% PAGO INICIAL]],10,0),"") -> 3000000 | I18: =IFERROR(VLOOKUP(F8,Tabla3[[#All],[CC-ID-DNI]:[% NUBE]],20,0),"") -> 0
E20: BILLETE DE ZIMBABWE | F20: =IFERROR(VLOOKUP($F$8,Tabla3[[CC-ID-DNI]:[1% PAGO INICIAL]],11,0),"") -> 0 | G20: =IFERROR(VLOOKUP($F$8,Tabla3[[#All],[CC-ID-DNI]:[1% PAGO INICIAL]],12,0),"") -> 0 | I20: NUBE
E22: AGROCHEQUE ZIM | F22: =IFERROR(VLOOKUP($F$8,Tabla3[[CC-ID-DNI]:[1% PAGO INICIAL]],13,0),"") -> 0 | G22: =IFERROR(VLOOKUP($F$8,Tabla3[[#All],[CC-ID-DNI]:[1% PAGO INICIAL]],14,0),"") -> 0 | I22: =IFERROR(VLOOKUP(F8,Tabla3[[#All],[CC-ID-DNI]:[% NUBE]],21,0),"") -> 1294623000
E24: OTROS | F24: =IFERROR(VLOOKUP($F$8,Tabla3[[CC-ID-DNI]:[1% PAGO INICIAL]],15,0),"") -> 0 | G24: =IFERROR(VLOOKUP($F$8,Tabla3[[#All],[CC-ID-DNI]:[1% PAGO INICIAL]],16,0),"") -> 0
E26: TOTAL | G26: TOTAL -10%
E28: =SUM(G12:G24) -> 1453000000 | G28: =E28-(E28*10%) -> 1307700000

Sheet RESUMEN GENERAL
E3: LIDER: | F3: =('MATRIZ LISTADO'!D16) -> JOHANA CASTAÑEDA
F6: CANT | G6: PAGO
E7: QUINTILLION | F7: =SUM(Tabla3[CANT]) -> 2762 | G7: =(F7*5000000) -> 13810000000
E9: NONGENTILLION | F9: =SUM(Tabla3[CANT2]) -> 442 | G9: =(F9*10000000) -> 4420000000
E11: VIGINTILLION | F11: =SUM(Tabla3[CANT3]) -> 265 | G11: =(F11*7500000) -> 1987500000
E13: MONEDA DE ZIM | F13: =SUM(Tabla3[CANT4]) -> 75 | G13: =(F13*500000) -> 37500000
E15: BILLETE DE ZIMBABWE | F15: =SUM(Tabla3[CANT5]) -> 2 | G15: =(F15*12500000) -> 25000000
E17: AGROCHEQUE ZIM | F17: =SUM(Tabla3[CANT6]) -> 5 | G17: =(F17*500000) -> 2500000
E19: MHK | F19: 20 | G19: =(F19*15000000) -> 300000000
E21: GOOGOPLEX | F21: 1 | G21: =(F21*500000000) -> 500000000
E23: TOTAL | G23: TOTAL -10% | I23: 1% PAGO BANCO
E25: =SUM(G7:G21) -> 21082500000 | G25: =E25-(E25*10%) -> 18974250000 | I25: =(G25*1%) -> 189742500
