Workbook

Sheet DATOS GENERALES
A1: FECHA | B1: NOMBRE COMPLETO | C1: ID/CC/DNI | D1: PASAPORTE | E1: PAIS | F1: ESTADO | G1: CIUDAD | H1: DIRECCION | I1: COD POSTAL | J1: CORREO | K1: TELEFONO | L1: PRODUCTO / MATERIAL | M1: MONTO | N1: REF | O1: BANK | P1: LIDER | Q1: CIS | R1: PASAPORTE + 3 MESES | S1: OBSERVACIONES | T1: CIS PARA IMPRIMIR
A2: 46128 | B2: ANGELICA OSPINA IZQUIERDO | C2: 65698739 | D2: N/A | E2: COLOMBIA | F2: TOLIMA | G2: ESPINAL | H2: MNZ O CS 7 JUAN PABLO II ETAPA 2 | I2: 733520 | J2: angelicaosiz25@gmail.com | K2: (+57) 3017857242 | L2: 2Q | M2: 100000 | N2: 437678 | O2: WOMPI | P2: ELIZABETH QUIROGA | Q2: PENDIENTE | R2: N/A
A3: 46129.858 | B3: ANGELICA OSPINA IZQUIERDO | C3: 65698739 | D3: N/A | E3: COLOMBIA | F3: TOLIMA | G3: ESPINAL | H3: MNZ O CS 7 JUAN PABLO II ETAPA 2 | I3: 733520 | J3: angelicaosiz25@gmail.com | K3: (+57) 3017857242 | L3: 1Q | M3: 0 | N3: GIRO RULETA | O3: N/A | P3: ELIZABETH QUIROGA | Q3: PENDIENTE | R3: N/A
A4: 46150 | B4: AURA MARIA RODRIGUEZ BURGOS | C4: 1070022846 | D4: AU450197 | E4: COLOMBIA | F4: CUNDINAMARCA | G4: RICAURTE | H4: CALLE 12 # 13 01 CONJUNTO CARIOTA LAS PALMAS APTO 608 TORRE3 | I4: 252410 | J4: aurismarobu@gmail.com | K4: (+57) 3132752680 | L4: 3N+3V | M4: 200000 | N4: 54502780298271954924066534667064412 | O4: NU BANK | P4: ELIZABETH QUIROGA | Q4: PENDIENTE | R4: VIGENTE
A5: 46150 | B5: AURA MARIA RODRIGUEZ BURGOS | C5: 1070022846 | D5: AU450197 | E5: COLOMBIA | F5: CUNDINAMARCA | G5: RICAURTE | H5: CALLE 12 # 13 01 CONJUNTO CARIOTA LAS PALMAS APTO 608 TORRE3 | I5: 252410 | J5: aurismarobu@gmail.com | K5: (+57) 3132752680 | L5: 2N | M5: 0 | N5: GIRO RULETA | O5: N/A | P5: ELIZABETH QUIROGA | Q5: PENDIENTE | R5: VIGENTE
A6: 45888.801 | B6: BLANCA ELIZABETH QUIROGA CASTIBLANCO | C6: 51760534 | D6: AY498421 | E6: COLOMBIA | F6: CUNDINAMARCA | G6: GIRARDOT | H6: CALLE 16 NO 2 45 ALTO DE LA CRUZ | I6: 252432 | J6: elizitaquiroga4@gmail.com | K6: (+57) 3015672778 | L6: 1V | M6: 120000 | N6: M15586657 | O6: NEQUI | P6: ELIZABETH QUIROGA | Q6: PENDIENTE | R6: VIGENTE
A7: 45922 | B7: BLANCA ELIZABETH QUIROGA CASTIBLANCO | C7: 51760534 | D7: AY498421 | E7: Colombia | F7: CUNDINAMARCA | G7: GIRARDOT | H7: CALLE 16 No 2 45 ALTO DE LA CRUZ | I7: 252432 | J7: elizitaquiroga4@gmail.com | K7: (+57) 3015672778 | L7: 1Q | M7: 0 | N7: VALLE DE TENZA | O7: N/A | P7: ELIZABETH QUIROGA | Q7: PENDIENTE | R7: VIGENTE
A8: 45932 | B8: BLANCA ELIZABETH QUIROGA CASTIBLANCO | C8: 51760534 | D8: AY498421 | E8: Colombia | F8: CUNDINAMARCA | G8: GIRARDOT | H8: CALLE 16 No 2 45 ALTO DE LA CRUZ | I8: 252432 | J8: elizitaquiroga4@gmail.com | K8: (+57) 3015672778 | L8: 2Q | M8: 0 | N8: RECUPERACIÓN | O8: N/A | P8: ELIZABETH QUIROGA | Q8: PENDIENTE | R8: VIGENTE
A9: 45968 | B9: BLANCA ELIZABETH QUIROGA CASTIBLANCO | C9: 51760534 | D9: AY498421 | E9: Colombia | F9: CUNDINAMARCA | G9: GIRARDOT | H9: CALLE 16 No 2 45 ALTO DE LA CRUZ | I9: 252432 | J9: elizitaquiroga4@gmail.com | K9: (+57) 3015672778 | L9: 14V | M9: 0 | N9: 25 SEP - 4 NOV | O9: N/A | P9: ELIZABETH QUIROGA | Q9: PENDIENTE | R9: VIGENTE
A10: 46022 | B10: BLANCA ELIZABETH QUIROGA CASTIBLANCO | C10: 51760534 | D10: AY498421 | E10: Colombia | F10: CUNDINAMARCA | G10: GIRARDOT | H10: CALLE 16 No 2 45 ALTO DE LA CRUZ | I10: 252432 | J10: elizitaquiroga4@gmail.com | K10: (+57) 3015672778 | L10: 1AGRO+1N | M10: 0 | N10: SORTEO | O10: PREMIO | P10: ELIZABETH QUIROGA | Q10: PENDIENTE | R10: VIGENTE
A11: 46126 | B11: BLANCA ELIZABETH QUIROGA CASTIBLANCO | C11: 51760534 | D11: AY498421 | E11: Colombia | F11: CUNDINAMARCA | G11: GIRARDOT | H11: CALLE 16 No 2 45 ALTO DE LA CRUZ | I11: 252432 | J11: elizitaquiroga4@gmail.com | K11: (+57) 3015672778 | L11: 2ZIMCOIN | M11: 0 | N11: X VENTAS HASTA EL 7 ABRIL | O11: N/A | P11: ELIZABETH QUIROGA | Q11: PENDIENTE | R11: VIGENTE
A12: 46128.441 | B12: BLANCA ELIZABETH QUIROGA CASTIBLANCO | C12: 51760534 | D12: AY498421 | E12: Colombia | F12: CUNDINAMARCA | G12: GIRARDOT | H12: CALLE 16 No 2 45 ALTO DE LA CRUZ | I12: 252432 | J12: elizitaquiroga4@gmail.com | K12: (+57) 3015672778 | L12: 1Q | M12: 0 | N12: GIRO RULETA | O12: N/A | P12: ELIZABETH QUIROGA | Q12: PENDIENTE | R12: VIGENTE
A13: 46148 | B13: BLANCA ELIZABETH QUIROGA CASTIBLANCO | C13: 51760534 | D13: AY498421 | E13: Colombia | F13: CUNDINAMARCA | G13: GIRARDOT | H13: CALLE 16 No 2 45 ALTO DE LA CRUZ | I13: 252432 | J13: elizitaquiroga4@gmail.com | K13: (+57) 3015672778 | L13: 3Q+1V | M13: 100000 | N13: M10315734 | O13: NEQUI | P13: ELIZABETH QUIROGA | Q13: PENDIENTE | R13: VIGENTE
A14: 46154.707 | B14: BLANCA ELIZABETH QUIROGA CASTIBLANCO | C14: 51760534 | D14: AY498421 | E14: Colombia | F14: CUNDINAMARCA | G14: GIRARDOT | H14: CALLE 16 No 2 45 ALTO DE LA CRUZ | I14: 252432 | J14: elizitaquiroga4@gmail.com | K14: (+57) 3015672778 | L14: 2V | M14: 0 | N14: GIRO RULETA | O14: N/A | P14: ELIZABETH QUIROGA | Q14: PENDIENTE | R14: VIGENTE
... A27: 46128.553 | B27: DILIA MARIA JAIMES RICHOUX | C27: 41650899 | D27: AR 294530 | E27: UNITED STATES | F27: FLORIDA | G27: MIAMI | H27: 401GOLDEN ISLES DR APT 513 HALLANDALE 33009-7515 BEACH FLORIDA | I27: 33009 | J27: dmjaimesr56@gmail.com | K27: (+1) 7868209437 | L27: 2V | M27: 0 | N27: GIRO RULETA | O27: N/A | P27: ELIZABETH QUIROGA | Q27: PENDIENTE | R27: N/A
A28: 46048 | B28: DORA CECILIA HUERTAS PRIETO | C28: 28844684 | D28: N/A | E28: COLOMBIA | F28: CUNDINAMARCA | G28: GIRARDOT | H28: KR 18 NO 22 85 AP 202 | I28: 252431 | J28: doraprieto032@gmail.com | K28: (+57) 3213212471 | L28: 6Q | M28: 150000 | N28: M11313089 | O28: NEQUI | P28: ELIZABETH QUIROGA | Q28: ENVIADO | R28: N/A | T28: ENVIADO EN PDF
A29: 45918.905 | B29: ELVIRA ROJAS RIVERA | C29: 38225833 | D29: BE886607 | E29: COLOMBIA | F29: TOLIMA | G29: FLANDES | H29: VIA FLANDERS ESPINALKLM1 MANZ G CASA2-27 CASA 32 CONDOMINIO LOS MANGOS II | I29: 733510 | J29: elvirarojas1552@gmail.com | K29: (+57) 3124327792 | L29: 1Q+1N+2V | M29: 200000 | N29: M21797085 | O29: NEQUI | P29: ELIZABETH QUIROGA | Q29: PENDIENTE | R29: VIGENTE
A30: 45930 | B30: ELVIRA ROJAS RIVERA | C30: 38225833 | D30: BE886607 | E30: COLOMBIA | F30: TOLIMA | G30: FLANDES | H30: VIA FLANDERS ESPINALKLM1 MANZ G CASA2-27 CASA 32 CONDOMINIO LOS MANGOS II | I30: 733510 | J30: elvirarojas1552@gmail.com | K30: (+57) 3124327792 | L30: 2Q+3N+2V | M30: 300000 | N30: M24465603 | O30: NEQUI | P30: ELIZABETH QUIROGA | Q30: PENDIENTE | R30: VIGENTE
A31: 45945 | B31: ELVIRA ROJAS RIVERA | C31: 38225833 | D31: BE886607 | E31: COLOMBIA | F31: TOLIMA | G31: FLANDES | H31: VIA FLANDERS ESPINALKLM1 MANZ G CASA2-27 CASA 32 CONDOMINIO LOS MANGOS II | I31: 733510 | J31: elvirarojas1552@gmail.com | K31: (+57) 3124327792 | L31: 1Q+1N+1V | M31: 200000 | N31: M20899682 | O31: NEQUI | P31: ELIZABETH QUIROGA | Q31: PENDIENTE | R31: VIGENTE
A32: 46078 | B32: ELVIRA ROJAS RIVERA | C32: 38225833 | D32: BE886607 | E32: COLOMBIA | F32: TOLIMA | G32: FLANDES | H32: VIA FLANDERS ESPINALKLM1 MANZ G CASA2-27 CASA 32 CONDOMINIO LOS MANGOS II | I32: 733510 | J32: elvirarojas1552@gmail.com | K32: (+57) 3124327792 | L32: 1ZIMCOIN | M32: 500000 | N32: M20150899 | O32: NEQUI | P32: ELIZABETH QUIROGA | Q32: PENDIENTE | R32: VIGENTE
A33: 45936.398 | B33: FERNANDO ALFONSO OVALLE GUTIERREZ | C33: 11315053 | D33: BG689137 | E33: COLOMBIA | F33: CUNDINAMARCA | G33: GIRARDOT | H33: Calle 21A #4-08 | I33: 252431 | J33: fernandoovalle13@hotmail.com | K33: (+57) 3232339799 | L33: 2Q+3N+2V | M33: 0 | N33: DOLLAR GOLD | O33: N/A | P33: ELIZABETH QUIROGA | Q33: ENVIADO | R33: VIGENTE | T33: ENVIADO EN PDF
A34: 46146 | B34: FERNANDO ALFONSO OVALLE GUTIERREZ | C34: 11315053 | D34: BG689137 | E34: COLOMBIA | F34: CUNDINAMARCA | G34: GIRARDOT | H34: Calle 21A #4-08 | I34: 252431 | J34: fernandoovalle13@hotmail.com | K34: (+57) 3232339799 | L34: 3Q+4N+3V | M34: 300000 | N34: TRPLLnGbw9EC | O34: BANCOLOMBIA | P34: ELIZABETH QUIROGA | Q34: ENVIADO | R34: VIGENTE | T34: ENVIADO EN PDF
A35: 46146.742 | B35: FERNANDO ALFONSO OVALLE GUTIERREZ | C35: 11315053 | D35: BG689137 | E35: COLOMBIA | F35: CUNDINAMARCA | G35: GIRARDOT | H35: Calle 21A #4-08 | I35: 252431 | J35: fernandoovalle13@hotmail.com | K35: (+57) 3232339799 | L35: 2Q | M35: 0 | N35: GIRO RULETA | O35: N/A | P35: ELIZABETH QUIROGA | Q35: ENVIADO | R35: VIGENTE | T35: ENVIADO EN PDF
A36: 46146.744 | B36: FERNANDO ALFONSO OVALLE GUTIERREZ | C36: 11315053 | D36: BG689137 | E36: COLOMBIA | F36: CUNDINAMARCA | G36: GIRARDOT | H36: Calle 21A #4-08 | I36: 252431 | J36: fernandoovalle13@hotmail.com | K36: (+57) 3232339799 | L36: 2V | M36: 0 | N36: GIRO RULETA | O36: N/A | P36: ELIZABETH QUIROGA | Q36: ENVIADO | R36: VIGENTE | T36: ENVIADO EN PDF
A37: 46146.746 | B37: FERNANDO ALFONSO OVALLE GUTIERREZ | C37: 11315053 | D37: BG689137 | E37: COLOMBIA | F37: CUNDINAMARCA | G37: GIRARDOT | H37: Calle 21A #4-08 | I37: 252431 | J37: fernandoovalle13@hotmail.com | K37: (+57) 3232339799 | L37: 2Q | M37: 0 | N37: GIRO RULETA | O37: N/A | P37: ELIZABETH QUIROGA | Q37: ENVIADO | R37: VIGENTE | T37: ENVIADO EN PDF
A38: 46150 | B38: FERNANDO ALFONSO OVALLE GUTIERREZ | C38: 11315053 | D38: BG689137 | E38: COLOMBIA | F38: CUNDINAMARCA | G38: GIRARDOT | H38: Calle 21A #4-08 | I38: 252431 | J38: fernandoovalle13@hotmail.com | K38: (+57) 3232339799 | L38: 6N | M38: 0 | N38: REFERIDOS | O38: N/A | P38: ELIZABETH QUIROGA | Q38: ENVIADO | R38: VIGENTE | T38: ENVIADO EN PDF
A39: 46150 | B39: GABRIEL HERNANDEZ MARTINEZ | C39: 80355504 | D39: N/A | E39: COLOMBIA | F39: CUNDINAMARCA | G39: GIRARDOT | H39: KR 18 NO 22 85 AP 202 | I39: 252431 | J39: gaherma1669@gmail.com | K39: (+57) 3214191758 | L39: 3Q+1V | M39: 100000 | N39: M15370261 | O39: NEQUI | P39: ELIZABETH QUIROGA | Q39: ENVIADO | R39: N/A | T39: ENVIADO EN PDF
A40: 46015 | B40: GERMAN MEDINA SARMIENTO | C40: 13460654 | D40: BH935354 | E40: COLOMBIA | F40: CUNDINAMARCA | G40: FUSAGASUGA | H40: KR 11 C NO 18 C 55 AP 202 | I40: 252212 | J40: medinasgerman@gmail.com | K40: (+57) 3163198485 | L40: 3Q+1N+1V | M40: 100000 | N40: M14982855 | O40: NEQUI | P40: ELIZABETH QUIROGA | Q40: PENDIENTE | R40: VIGENTE
A41: 46050 | B41: GERMAN MEDINA SARMIENTO | C41: 13460654 | D41: BH935354 | E41: COLOMBIA | F41: CUNDINAMARCA | G41: FUSAGASUGA | H41: KR 11 C NO 18 C 55 AP 202 | I41: 252212 | J41: medinasgerman@gmail.com | K41: (+57) 3163198485 | L41: COFRE | M41: 100000 | N41: M18602116 | O41: NEQUI | P41: ELIZABETH QUIROGA | Q41: PENDIENTE | R41: VIGENTE
A42: 46057 | B42: GERMAN MEDINA SARMIENTO | C42: 13460654 | D42: BH935354 | E42: COLOMBIA | F42: CUNDINAMARCA | G42: FUSAGASUGA | H42: KR 11 C NO 18 C 55 AP 202 | I42: 252212 | J42: medinasgerman@gmail.com | K42: (+57) 3163198485 | L42: 6Q | M42: 150000 | N42: M11905052 | O42: NEQUI | P42: ELIZABETH QUIROGA | Q42: PENDIENTE | R42: VIGENTE
A43: 46149 | B43: GILBERTO DEVIA QUIÑONES | C43: 14370092 | D43: BF168899 | E43: COLOMBIA | F43: BOGOTA D.C. | G43: BOGOTA | H43: CALLE 60 SUR # 71-50- / 77-01 BALMORAL TERCERA ETAPA | I43: 111941 | J43: gilbertodevia5@gmail.com | K43: (+57) 3122364080 | L43: 3Q+1V | M43: 100000 | N43: M23351394 | O43: NEQUI | P43: ELIZABETH QUIROGA | Q43: ENVIADO | R43: VIGENTE | T43: ENVIADO EN PDF
A44: 46149 | B44: GILBERTO DEVIA QUIÑONES | C44: 14370092 | D44: BF168899 | E44: COLOMBIA | F44: BOGOTA D.C. | G44: BOGOTA | H44: CALLE 60 SUR # 71-50- / 77-01 BALMORAL TERCERA ETAPA | I44: 111941 | J44: gilbertodevia5@gmail.com | K44: (+57) 3122364080 | L44: 1Q | M44: 0 | N44: GIRO RULETA | O44: N/A | P44: ELIZABETH QUIROGA | Q44: ENVIADO | R44: VIGENTE | T44: ENVIADO EN PDF
A45: 46057 | B45: GINA MILENA MORENO PERDOMO | C45: 1075231467 | D45: N/A | E45: COLOMBIA | F45: TOLIMA | G45: ESPINAL | H45: MANZANA E CASA 7 ASOBETANIA | I45: 733520 | J45: g_milena_mo@hotmail.com | K45: (+57) 3133075717 | L45: 6Q | M45: 150000 | N45: M13925241 | O45: NEQUI | P45: ELIZABETH QUIROGA | Q45: PENDIENTE | R45: N/A
A46: 46129 | B46: GRICELDA GUTIERREZ DE UBAQUE | C46: 20563430 | D46: N/A | E46: COLOMBIA | F46: CUNDINAMARCA | G46: FUSAGASUGA | H46: CARRERA 1B N 10A - 18 | I46: 252211 | J46: griceldagutierrez2009@gmail.com | K46: (+57) 3103294116 | L46: 5Q+2N | M46: 200000 | N46: f38df69e-f7a8-4201-84b1-583fcbf7e147 | O46: DAVIVIENDA | P46: ELIZABETH QUIROGA | Q46: PENDIENTE | R46: N/A
A47: 46129.829 | B47: GRICELDA GUTIERREZ DE UBAQUE | C47: 20563430 | D47: N/A | E47: COLOMBIA | F47: CUNDINAMARCA | G47: FUSAGASUGA | H47: CARRERA 1B N 10A - 18 | I47: 252211 | J47: griceldagutierrez2009@gmail.com | K47: (+57) 3103294116 | L47: 1V | M47: 0 | N47: GIRO RULETA | O47: N/A | P47: ELIZABETH QUIROGA | Q47: PENDIENTE | R47: N/A
A48: 46129.831 | B48: GRICELDA GUTIERREZ DE UBAQUE | C48: 20563430 | D48: N/A | E48: COLOMBIA | F48: CUNDINAMARCA | G48: FUSAGASUGA | H48: CARRERA 1B N 10A - 18 | I48: 252211 | J48: griceldagutierrez2009@gmail.com | K48: (+57) 3103294116 | L48: 1Q | M48: 0 | N48: GIRO RULETA | O48: N/A | P48: ELIZABETH QUIROGA | Q48: PENDIENTE | R48: N/A
A49: 45952.619 | B49: HARVEY NICOLÁS PARRA QUIROGA | C49: 1018473483 | D49: AV227068 | E49: COLOMBIA | F49: CUNDINAMARCA | G49: GIRARDOT | H49: CALLE 16 NO 2 45 ALTO DE LA CRUZ | I49: 252432 | J49: hnicolas.parra@gmail.com | K49: (+57) 3005548572 | L49: 2Q | M49: 100000 | N49: M14243030 | O49: NEQUI | P49: ELIZABETH QUIROGA | Q49: ENVIADO | R49: VIGENTE | T49: ENVIADO EN PDF
A50: 46150 | B50: HARVEY NICOLÁS PARRA QUIROGA | C50: 1018473483 | D50: AV227068 | E50: COLOMBIA | F50: CUNDINAMARCA | G50: GIRARDOT | H50: CALLE 16 NO 2 45 ALTO DE LA CRUZ | I50: 252432 | J50: hnicolas.parra@gmail.com | K50: (+57) 3005548572 | L50: 2N | M50: 0 | N50: REFERIDOS | O50: N/A | P50: ELIZABETH QUIROGA | Q50: ENVIADO | R50: VIGENTE | T50: ENVIADO EN PDF
A51: 46105 | B51: HORTENCIA NIÑO JUSTINICO | C51: 20647654 | D51: BI051653 | E51: COLOMBIA | F51: CUNDINAMARCA | G51: GIRARDOT | H51: MANZANA M CASA 4 CIUDAD MONTES | I51: 252432 | J51: hortencianino076@gmail.com | K51: (+57) 3204866107 | L51: 6Q+6N | M51: 500000 | N51: M18295502 | O51: NEQUI | P51: ELIZABETH QUIROGA | Q51: ENVIADO | R51: VIGENTE | T51: ENVIADO EN PDF
A52: 46145 | B52: HORTENCIA NIÑO JUSTINICO | C52: 20647654 | D52: BI051653 | E52: COLOMBIA | F52: CUNDINAMARCA | G52: GIRARDOT | H52: MANZANA M CASA 4 CIUDAD MONTES | I52: 252432 | J52: hortencianino076@gmail.com | K52: (+57) 3204866107 | L52: 4Q+6N+4V | M52: 500000 | N52: RK22A3345V | O52: BANCOLOMBIA | P52: ELIZABETH QUIROGA | Q52: ENVIADO | R52: VIGENTE | T52: ENVIADO EN PDF
...

Sheet MATRIZ LISTADO
V3: SI | W3: FIDUCIA
V4: NO | W4: NUBE
C16: LIDER: | D16: ELIZABETH QUIROGA
Y17: PORCENTAJES
B18: CC-ID-DNI | C18: NOMBRE | D18: QUINTILLION 5M | F18: NONGENTILLION 10M | H18: VIGINTILLION 7,5M | J18: MONEDA ZIMBABWE 500k | L18: BILLETE DE ZIMBABWE 12,5M | N18: AGROCHEQUE50M | P18: OTROS | R18: USD | S18: TOTAL -10% | T18: 1% PAGO INICIAL | U18: FIDUCIA | V18: NUBE | W18: SKR SI/NO | X18: FIDUCIA/NUBE | Y18: BANCO | Z18: FIDUCIA | AA18: NUBE | AB18: TOTAL
A19: LISTA | B19: CC-ID-DNI | C19: NOMBRE | D19: CANT | E19: MONTO | F19: CANT2 | G19: MONTO2 | H19: CANT3 | I19: MONTO3 | J19: CANT4 | K19: MONTO4 | L19: CANT5 | M19: MONTO5 | N19: CANT6 | O19: MONTO6 | P19: CANT7 | Q19: MONTO7 | R19: USD | S19: TOTAL -10% | T19: 1% PAGO INICIAL | U19: % FIDUCIA | V19: % NUBE | W19: SKR SI/NO | X19: FIDUCIA/NUBE | Y19: BANCO | Z19: FIDUCIA | AA19: NUBE | AB19: 100%
A20: 1 | B20: 65698739 | C20: ANGELICA OSPINA IZQUIERDO | D20: 3 | E20: =(Tabla3[[#This Row],[CANT]]*5000000) -> 15000000 | R20: =(Tabla3[[#This Row],[MONTO]]+Tabla3[[#This Row],[MONTO2]]+Tabla3[[#This Row],[MONTO3]]+Tabla3[[#This Row],[MONTO4]]+Tabla3[[#This Row],[MONTO5]]+Tabla3[[#This Row],[MONTO6]]+Tabla3[[#This Row],[MONTO7]]) -> 15000000 | S20: =R20-(R20*10%) -> 13500000 | T20: =(S20*1%) -> 135000 | U20: =(Tabla3[[#This Row],[TOTAL -10%]]*Tabla3[[#This Row],[FIDUCIA]]) -> 13365000 | V20: =(Tabla3[[#This Row],[TOTAL -10%]]*Tabla3[[#This Row],[NUBE]]) -> 0 | W20: SI | X20: FIDUCIA | Y20: 0.01 | Z20: 0.99 | AB20: =SUM(Y20:AA20) -> 1 | AC20: =IF(AB20="","",IF(AB20=100%,"OK","ERROR")) -> OK
A21: =(A20+1) -> 2 | B21: 1070022846 | C21: AURA MARIA RODRIGUEZ BURGOS | F21: 5 | G21: 50000000 | H21: 3 | I21: 22500000 | R21: =(Tabla3[[#This Row],[MONTO]]+Tabla3[[#This Row],[MONTO2]]+Tabla3[[#This Row],[MONTO3]]+Tabla3[[#This Row],[MONTO4]]+Tabla3[[#This Row],[MONTO5]]+Tabla3[[#This Row],[MONTO6]]+Tabla3[[#This Row],[MONTO7]]) -> 72500000 | S21: =R21-(R21*10%) -> 65250000 | T21: =(S21*1%) -> 652500 | U21: =(Tabla3[[#This Row],[TOTAL -10%]]*Tabla3[[#This Row],[FIDUCIA]]) -> 64597500 | V21: =(Tabla3[[#This Row],[TOTAL -10%]]*Tabla3[[#This Row],[NUBE]]) -> 0 | W21: SI | X21: FIDUCIA | Y21: 0.01 | Z21: 0.99 | AB21: =SUM(Y21:AA21) -> 1 | AC21: =IF(AB21="","",IF(AB21=100%,"OK","ERROR")) -> OK
A22: =(A21+1) -> 3 | B22: 51760534 | C22: BLANCA ELIZABETH QUIROGA CASTIBLANCO | D22: 1142 | E22: =(Tabla3[[#This Row],[CANT]]*5000000) -> 5710000000 | F22: 1 | G22: 10000000 | H22: 22 | I22: 165000000 | J22: 2 | K22: 1000000 | N22: 1 | O22: =(Tabla3[[#This Row],[CANT6]]*200000) -> 200000 | R22: =(Tabla3[[#This Row],[MONTO]]+Tabla3[[#This Row],[MONTO2]]+Tabla3[[#This Row],[MONTO3]]+Tabla3[[#This Row],[MONTO4]]+Tabla3[[#This Row],[MONTO5]]+Tabla3[[#This Row],[MONTO6]]+Tabla3[[#This Row],[MONTO7]]) -> 5886200000 | S22: =R22-(R22*10%) -> 5297580000 | T22: =(S22*1%) -> 52975800 | U22: =(Tabla3[[#This Row],[TOTAL -10%]]*Tabla3[[#This Row],[FIDUCIA]]) -> 2119032000 | V22: =(Tabla3[[#This Row],[TOTAL -10%]]*Tabla3[[#This Row],[NUBE]]) -> 3125572200 | W22: SI | X22: FIDUCIA/NUBE | Y22: 0.01 | Z22: 0.4 | AA22: 0.59 | AB22: =SUM(Y22:AA22) -> 1 | AC22: =IF(AB22="","",IF(AB22=100%,"OK","ERROR")) -> OK
A23: =(A22+1) -> 4 | B23: 16266851 | C23: CARLOS ERNESTO PAZ CABAL | D23: 2 | E23: =(Tabla3[[#This Row],[CANT]]*5000000) -> 10000000 | F23: 3 | G23: 30000000 | H23: 2 | I23: 15000000 | R23: =(Tabla3[[#This Row],[MONTO]]+Tabla3[[#This Row],[MONTO2]]+Tabla3[[#This Row],[MONTO3]]+Tabla3[[#This Row],[MONTO4]]+Tabla3[[#This Row],[MONTO5]]+Tabla3[[#This Row],[MONTO6]]+Tabla3[[#This Row],[MONTO7]]) -> 55000000 | S23: =R23-(R23*10%) -> 49500000 | T23: =(S23*1%) -> 495000 | U23: =(Tabla3[[#This Row],[TOTAL -10%]]*Tabla3[[#This Row],[FIDUCIA]]) -> 49005000 | V23: =(Tabla3[[#This Row],[TOTAL -10%]]*Tabla3[[#This Row],[NUBE]]) -> 0 | W23: SI | X23: FIDUCIA | Y23: 0.01 | Z23: 0.99 | AB23: =SUM(Y23:AA23) -> 1 | AC23: =IF(AB23="","",IF(AB23=100%,"OK","ERROR")) -> OK
A24: =(A23+1) -> 5 | B24: 39585053 | C24: CONSUELO MONTEJO CASAS | D24: 2 | E24: =(Tabla3[[#This Row],[CANT]]*5000000) -> 10000000 | H24: 1 | I24: 7500000 | R24: =(Tabla3[[#This Row],[MONTO]]+Tabla3[[#This Row],[MONTO2]]+Tabla3[[#This Row],[MONTO3]]+Tabla3[[#This Row],[MONTO4]]+Tabla3[[#This Row],[MONTO5]]+Tabla3[[#This Row],[MONTO6]]+Tabla3[[#This Row],[MONTO7]]) -> 17500000 | S24: =R24-(R24*10%) -> 15750000 | T24: =(S24*1%) -> 157500 | U24: =(Tabla3[[#This Row],[TOTAL -10%]]*Tabla3[[#This Row],[FIDUCIA]]) -> 15592500 | V24: =(Tabla3[[#This Row],[TOTAL -10%]]*Tabla3[[#This Row],[NUBE]]) -> 0 | W24: SI | X24: FIDUCIA | Y24: 0.01 | Z24: 0.99 | AB24: =SUM(Y24:AA24) -> 1 | AC24: =IF(AB24="","",IF(AB24=100%,"OK","ERROR")) -> OK
A25: =(A24+1) -> 6 | B25: 7717811 | C25: CRISTOBAL VELEZ CAMACHO | D25: 9 | E25: =(Tabla3[[#This Row],[CANT]]*5000000) -> 45000000 | R25: =(Tabla3[[#This Row],[MONTO]]+Tabla3[[#This Row],[MONTO2]]+Tabla3[[#This Row],[MONTO3]]+Tabla3[[#This Row],[MONTO4]]+Tabla3[[#This Row],[MONTO5]]+Tabla3[[#This Row],[MONTO6]]+Tabla3[[#This Row],[MONTO7]]) -> 45000000 | S25: =R25-(R25*10%) -> 40500000 | T25: =(S25*1%) -> 405000 | U25: =(Tabla3[[#This Row],[TOTAL -10%]]*Tabla3[[#This Row],[FIDUCIA]]) -> 40095000 | V25: =(Tabla3[[#This Row],[TOTAL -10%]]*Tabla3[[#This Row],[NUBE]]) -> 0 | W25: SI | X25: FIDUCIA | Y25: 0.01 | Z25: 0.99 | AB25: =SUM(Y25:AA25) -> 1 | AC25: =IF(AB25="","",IF(AB25=100%,"OK","ERROR")) -> OK
A26: =(A25+1) -> 7 | B26: 1106896741 | C26: CRISTIAN CAMILO CALDERON CHARRY | D26: 4 | E26: =(Tabla3[[#This Row],[CANT]]*5000000) -> 20000000 | H26: 1 | I26: 7500000 | R26: =(Tabla3[[#This Row],[MONTO]]+Tabla3[[#This Row],[MONTO2]]+Tabla3[[#This Row],[MONTO3]]+Tabla3[[#This Row],[MONTO4]]+Tabla3[[#This Row],[MONTO5]]+Tabla3[[#This Row],[MONTO6]]+Tabla3[[#This Row],[MONTO7]]) -> 27500000 | S26: =R26-(R26*10%) -> 24750000 | T26: =(S26*1%) -> 247500 | U26: =(Tabla3[[#This Row],[TOTAL -10%]]*Tabla3[[#This Row],[FIDUCIA]]) -> 0 | V26: =(Tabla3[[#This Row],[TOTAL -10%]]*Tabla3[[#This Row],[NUBE]]) -> 24502500 | W26: SI | X26: NUBE | Y26: 0.01 | AA26: 0.99 | AB26: =SUM(Y26:AA26) -> 1 | AC26: =IF(AB26="","",IF(AB26=100%,"OK","ERROR")) -> OK
A27: =(A26+1) -> 8 | B27: 41650899 | C27: DILIA MARIA JAIMES RICHOUX | D27: 11 | E27: =(Tabla3[[#This Row],[CANT]]*5000000) -> 55000000 | F27: 2 | G27: 20000000 | H27: 2 | I27: 15000000 | R27: =(Tabla3[[#This Row],[MONTO]]+Tabla3[[#This Row],[MONTO2]]+Tabla3[[#This Row],[MONTO3]]+Tabla3[[#This Row],[MONTO4]]+Tabla3[[#This Row],[MONTO5]]+Tabla3[[#This Row],[MONTO6]]+Tabla3[[#This Row],[MONTO7]]) -> 90000000 | S27: =R27-(R27*10%) -> 81000000 | T27: =(S27*1%) -> 810000 | U27: =(Tabla3[[#This Row],[TOTAL -10%]]*Tabla3[[#This Row],[FIDUCIA]]) -> 80190000 | V27: =(Tabla3[[#This Row],[TOTAL -10%]]*Tabla3[[#This Row],[NUBE]]) -> 0 | W27: SI | X27: FIDUCIA | Y27: 0.01 | Z27: 0.99 | AB27: =SUM(Y27:AA27) -> 1 | AC27: =IF(AB27="","",IF(AB27=100%,"OK","ERROR")) -> OK
A28: =(A27+1) -> 9 | B28: 28844684 | C28: DORA CECILIA HUERTAS PRIETO | D28: 6 | E28: =(Tabla3[[#This Row],[CANT]]*5000000) -> 30000000 | R28: =(Tabla3[[#This Row],[MONTO]]+Tabla3[[#This Row],[MONTO2]]+Tabla3[[#This Row],[MONTO3]]+Tabla3[[#This Row],[MONTO4]]+Tabla3[[#This Row],[MONTO5]]+Tabla3[[#This Row],[MONTO6]]+Tabla3[[#This Row],[MONTO7]]) -> 30000000 | S28: =R28-(R28*10%) -> 27000000 | T28: =(S28*1%) -> 270000 | U28: =(Tabla3[[#This Row],[TOTAL -10%]]*Tabla3[[#This Row],[FIDUCIA]]) -> 0 | V28: =(Tabla3[[#This Row],[TOTAL -10%]]*Tabla3[[#This Row],[NUBE]]) -> 26730000 | W28: SI | X28: NUBE | Y28: 0.01 | AA28: 0.99 | AB28: =SUM(Y28:AA28) -> 1 | AC28: =IF(AB28="","",IF(AB28=100%,"OK","ERROR")) -> OK
A29: =(A28+1) -> 10 | B29: 38225833 | C29: ELVIRA ROJAS RIVERA | D29: 4 | E29: =(Tabla3[[#This Row],[CANT]]*5000000) -> 20000000 | F29: 5 | G29: 50000000 | H29: 5 | I29: 37500000 | J29: 1 | K29: 500000 | R29: =(Tabla3[[#This Row],[MONTO]]+Tabla3[[#This Row],[MONTO2]]+Tabla3[[#This Row],[MONTO3]]+Tabla3[[#This Row],[MONTO4]]+Tabla3[[#This Row],[MONTO5]]+Tabla3[[#This Row],[MONTO6]]+Tabla3[[#This Row],[MONTO7]]) -> 108000000 | S29: =R29-(R29*10%) -> 97200000 | T29: =(S29*1%) -> 972000 | U29: =(Tabla3[[#This Row],[TOTAL -10%]]*Tabla3[[#This Row],[FIDUCIA]]) -> 96228000 | V29: =(Tabla3[[#This Row],[TOTAL -10%]]*Tabla3[[#This Row],[NUBE]]) -> 0 | W29: SI | X29: FIDUCIA | Y29: 0.01 | Z29: 0.99 | AB29: =SUM(Y29:AA29) -> 1 | AC29: =IF(AB29="","",IF(AB29=100%,"OK","ERROR")) -> OK
A30: =(A29+1) -> 11 | B30: 11315053 | C30: FERNANDO ALFONSO OVALLE GUTIERREZ | D30: 9 | E30: =(Tabla3[[#This Row],[CANT]]*5000000) -> 45000000 | F30: 13 | G30: 130000000 | H30: 7 | I30: 52500000 | R30: =(Tabla3[[#This Row],[MONTO]]+Tabla3[[#This Row],[MONTO2]]+Tabla3[[#This Row],[MONTO3]]+Tabla3[[#This Row],[MONTO4]]+Tabla3[[#This Row],[MONTO5]]+Tabla3[[#This Row],[MONTO6]]+Tabla3[[#This Row],[MONTO7]]) -> 227500000 | S30: =R30-(R30*10%) -> 204750000 | T30: =(S30*1%) -> 2047500 | U30: =(Tabla3[[#This Row],[TOTAL -10%]]*Tabla3[[#This Row],[FIDUCIA]]) -> 0 | V30: =(Tabla3[[#This Row],[TOTAL -10%]]*Tabla3[[#This Row],[NUBE]]) -> 202702500 | W30: SI | X30: NUBE | Y30: 0.01 | AA30: 0.99 | AB30: =SUM(Y30:AA30) -> 1 | AC30: =IF(AB30="","",IF(AB30=100%,"OK","ERROR")) -> OK
A31: =(A30+1) -> 12 | B31: 80355504 | C31: GABRIEL HERNANDEZ MARTINEZ | D31: 3 | E31: =(Tabla3[[#This Row],[CANT]]*5000000) -> 15000000 | H31: 1 | I31: 7500000 | R31: =(Tabla3[[#This Row],[MONTO]]+Tabla3[[#This Row],[MONTO2]]+Tabla3[[#This Row],[MONTO3]]+Tabla3[[#This Row],[MONTO4]]+Tabla3[[#This Row],[MONTO5]]+Tabla3[[#This Row],[MONTO6]]+Tabla3[[#This Row],[MONTO7]]) -> 22500000 | S31: =R31-(R31*10%) -> 20250000 | T31: =(S31*1%) -> 202500 | U31: =(Tabla3[[#This Row],[TOTAL -10%]]*Tabla3[[#This Row],[FIDUCIA]]) -> 0 | V31: =(Tabla3[[#This Row],[TOTAL -10%]]*Tabla3[[#This Row],[NUBE]]) -> 20047500 | W31: SI | X31: NUBE | Y31: 0.01 | AA31: 0.99 | AB31: =SUM(Y31:AA31) -> 1 | AC31: =IF(AB31="","",IF(AB31=100%,"OK","ERROR")) -> OK
A32: =(A31+1) -> 13 | B32: 13460654 | C32: GERMAN MEDINA SARMIENTO | D32: 9 | E32: =(Tabla3[[#This Row],[CANT]]*5000000) -> 45000000 | F32: 1 | G32: 10000000 | H32: 1 | I32: 7500000 | R32: =(Tabla3[[#This Row],[MONTO]]+Tabla3[[#This Row],[MONTO2]]+Tabla3[[#This Row],[MONTO3]]+Tabla3[[#This Row],[MONTO4]]+Tabla3[[#This Row],[MONTO5]]+Tabla3[[#This Row],[MONTO6]]+Tabla3[[#This Row],[MONTO7]]) -> 62500000 | S32: =R32-(R32*10%) -> 56250000 | T32: =(S32*1%) -> 562500 | U32: =(Tabla3[[#This Row],[TOTAL -10%]]*Tabla3[[#This Row],[FIDUCIA]]) -> 55687500 | V32: =(Tabla3[[#This Row],[TOTAL -10%]]*Tabla3[[#This Row],[NUBE]]) -> 0 | W32: SI | X32: FIDUCIA | Y32: 0.01 | Z32: 0.99 | AB32: =SUM(Y32:AA32) -> 1 | AC32: =IF(AB32="","",IF(AB32=100%,"OK","ERROR")) -> OK
A33: =(A32+1) -> 14 | B33: 14370092 | C33: GILBERTO DEVIA QUIÑONES | D33: 4 | E33: =(Tabla3[[#This Row],[CANT]]*5000000) -> 20000000 | H33: 1 | I33: 7500000 | R33: =(Tabla3[[#This Row],[MONTO]]+Tabla3[[#This Row],[MONTO2]]+Tabla3[[#This Row],[MONTO3]]+Tabla3[[#This Row],[MONTO4]]+Tabla3[[#This Row],[MONTO5]]+Tabla3[[#This Row],[MONTO6]]+Tabla3[[#This Row],[MONTO7]]) -> 27500000 | S33: =R33-(R33*10%) -> 24750000 | T33: =(S33*1%) -> 247500 | U33: =(Tabla3[[#This Row],[TOTAL -10%]]*Tabla3[[#This Row],[FIDUCIA]]) -> 24502500 | V33: =(Tabla3[[#This Row],[TOTAL -10%]]*Tabla3[[#This Row],[NUBE]]) -> 0 | W33: SI | X33: FIDUCIA | Y33: 0.01 | Z33: 0.99 | AB33: =SUM(Y33:AA33) -> 1 | AC33: =IF(AB33="","",IF(AB33=100%,"OK","ERROR")) -> OK
A34: =(A33+1) -> 15 | B34: 1075231467 | C34: GINA MILENA MORENO PERDOMO | D34: 6 | E34: =(Tabla3[[#This Row],[CANT]]*5000000) -> 30000000 | R34: =(Tabla3[[#This Row],[MONTO]]+Tabla3[[#This Row],[MONTO2]]+Tabla3[[#This Row],[MONTO3]]+Tabla3[[#This Row],[MONTO4]]+Tabla3[[#This Row],[MONTO5]]+Tabla3[[#This Row],[MONTO6]]+Tabla3[[#This Row],[MONTO7]]) -> 30000000 | S34: =R34-(R34*10%) -> 27000000 | T34: =(S34*1%) -> 270000 | U34: =(Tabla3[[#This Row],[TOTAL -10%]]*Tabla3[[#This Row],[FIDUCIA]]) -> 26730000 | V34: =(Tabla3[[#This Row],[TOTAL -10%]]*Tabla3[[#This Row],[NUBE]]) -> 0 | W34: SI | X34: FIDUCIA | Y34: 0.01 | Z34: 0.99 | AB34: =SUM(Y34:AA34) -> 1 | AC34: =IF(AB34="","",IF(AB34=100%,"OK","ERROR")) -> OK
A35: =(A34+1) -> 16 | B35: 20563430 | C35: GRICELDA GUTIERREZ | D35: 6 | E35: =(Tabla3[[#This Row],[CANT]]*5000000) -> 30000000 | F35: 2 | G35: 20000000 | H35: 1 | I35: 7500000 | R35: =(Tabla3[[#This Row],[MONTO]]+Tabla3[[#This Row],[MONTO2]]+Tabla3[[#This Row],[MONTO3]]+Tabla3[[#This Row],[MONTO4]]+Tabla3[[#This Row],[MONTO5]]+Tabla3[[#This Row],[MONTO6]]+Tabla3[[#This Row],[MONTO7]]) -> 57500000 | S35: =R35-(R35*10%) -> 51750000 | T35: =(S35*1%) -> 517500 | U35: =(Tabla3[[#This Row],[TOTAL -10%]]*Tabla3[[#This Row],[FIDUCIA]]) -> 51232500 | V35: =(Tabla3[[#This Row],[TOTAL -10%]]*Tabla3[[#This Row],[NUBE]]) -> 0 | W35: SI | X35: FIDUCIA | Y35: 0.01 | Z35: 0.99 | AB35: =SUM(Y35:AA35) -> 1 | AC35: =IF(AB35="","",IF(AB35=100%,"OK","ERROR")) -> OK
A36: =(A35+1) -> 17 | B36: 1018473483 | C36: HARVEY NICOLÁS PARRA QUIROGA | D36: 2 | E36: =(Tabla3[[#This Row],[CANT]]*5000000) -> 10000000 | F36: 2 | G36: 20000000 | R36: =(Tabla3[[#This Row],[MONTO]]+Tabla3[[#This Row],[MONTO2]]+Tabla3[[#This Row],[MONTO3]]+Tabla3[[#This Row],[MONTO4]]+Tabla3[[#This Row],[MONTO5]]+Tabla3[[#This Row],[MONTO6]]+Tabla3[[#This Row],[MONTO7]]) -> 30000000 | S36: =R36-(R36*10%) -> 27000000 | T36: =(S36*1%) -> 270000 | U36: =(Tabla3[[#This Row],[TOTAL -10%]]*Tabla3[[#This Row],[FIDUCIA]]) -> 10800000 | V36: =(Tabla3[[#This Row],[TOTAL -10%]]*Tabla3[[#This Row],[NUBE]]) -> 15930000 | W36: SI | X36: FIDUCIA/NUBE | Y36: 0.01 | Z36: 0.4 | AA36: 0.59 | AB36: =SUM(Y36:AA36) -> 1 | AC36: =IF(AB36="","",IF(AB36=100%,"OK","ERROR")) -> OK
A37: =(A36+1) -> 18 | B37: 20647654 | C37: HORTENCIA NIÑO JUSTINICO | D37: 16 | E37: =(Tabla3[[#This Row],[CANT]]*5000000) -> 80000000 | F37: 16 | G37: 160000000 | H37: 4 | I37: 30000000 | R37: =(Tabla3[[#This Row],[MONTO]]+Tabla3[[#This Row],[MONTO2]]+Tabla3[[#This Row],[MONTO3]]+Tabla3[[#This Row],[MONTO4]]+Tabla3[[#This Row],[MONTO5]]+Tabla3[[#This Row],[MONTO6]]+Tabla3[[#This Row],[MONTO7]]) -> 270000000 | S37: =R37-(R37*10%) -> 243000000 | T37: =(S37*1%) -> 2430000 | U37: =(Tabla3[[#This Row],[TOTAL -10%]]*Tabla3[[#This Row],[FIDUCIA]]) -> 0 | V37: =(Tabla3[[#This Row],[TOTAL -10%]]*Tabla3[[#This Row],[NUBE]]) -> 240570000 | W37: SI | X37: NUBE | Y37: 0.01 | AA37: 0.99 | AB37: =SUM(Y37:AA37) -> 1 | AC37: =IF(AB37="","",IF(AB37=100%,"OK","ERROR")) -> OK
A38: =(A37+1) -> 19 | B38: 31496340 | C38: JANETH BURITICA MEJIA | D38: 2 | E38: =(Tabla3[[#This Row],[CANT]]*5000000) -> 10000000 | F38: 1 | G38: 10000000 | R38: =(Tabla3[[#This Row],[MONTO]]+Tabla3[[#This Row],[MONTO2]]+Tabla3[[#This Row],[MONTO3]]+Tabla3[[#This Row],[MONTO4]]+Tabla3[[#This Row],[MONTO5]]+Tabla3[[#This Row],[MONTO6]]+Tabla3[[#This Row],[MONTO7]]) -> 20000000 | S38: =R38-(R38*10%) -> 18000000 | T38: =(S38*1%) -> 180000 | U38: =(Tabla3[[#This Row],[TOTAL -10%]]*Tabla3[[#This Row],[FIDUCIA]]) -> 17820000 | V38: =(Tabla3[[#This Row],[TOTAL -10%]]*Tabla3[[#This Row],[NUBE]]) -> 0 | W38: SI | X38: FIDUCIA | Y38: 0.01 | Z38: 0.99 | AB38: =SUM(Y38:AA38) -> 1 | AC38: =IF(AB38="","",IF(AB38=100%,"OK","ERROR")) -> OK
A39: =(A38+1) -> 20 | B39: 11315984 | C39: JAVIER FERNANDO DE LA ROCHE GUTIERREZ | D39: 12 | E39: =(Tabla3[[#This Row],[CANT]]*5000000) -> 60000000 | J39: 1 | K39: 500000 | R39: =(Tabla3[[#This Row],[MONTO]]+Tabla3[[#This Row],[MONTO2]]+Tabla3[[#This Row],[MONTO3]]+Tabla3[[#This Row],[MONTO4]]+Tabla3[[#This Row],[MONTO5]]+Tabla3[[#This Row],[MONTO6]]+Tabla3[[#This Row],[MONTO7]]) -> 60500000 | S39: =R39-(R39*10%) -> 54450000 | T39: =(S39*1%) -> 544500 | U39: =(Tabla3[[#This Row],[TOTAL -10%]]*Tabla3[[#This Row],[FIDUCIA]]) -> 53905500 | V39: =(Tabla3[[#This Row],[TOTAL -10%]]*Tabla3[[#This Row],[NUBE]]) -> 0 | W39: SI | X39: FIDUCIA | Y39: 0.01 | Z39: 0.99 | AB39: =SUM(Y39:AA39) -> 1 | AC39: =IF(AB39="","",IF(AB39=100%,"OK","ERROR")) -> OK
A40: =(A39+1) -> 21 | B40: 1015413288 | C40: JEYRON ERICK SANCHEZ DIAZ | D40: 9 | E40: =(Tabla3[[#This Row],[CANT]]*5000000) -> 45000000 | F40: 3 | G40: 30000000 | R40: =(Tabla3[[#This Row],[MONTO]]+Tabla3[[#This Row],[MONTO2]]+Tabla3[[#This Row],[MONTO3]]+Tabla3[[#This Row],[MONTO4]]+Tabla3[[#This Row],[MONTO5]]+Tabla3[[#This Row],[MONTO6]]+Tabla3[[#This Row],[MONTO7]]) -> 75000000 | S40: =R40-(R40*10%) -> 67500000 | T40: =(S40*1%) -> 675000 | U40: =(Tabla3[[#This Row],[TOTAL -10%]]*Tabla3[[#This Row],[FIDUCIA]]) -> 66825000 | V40: =(Tabla3[[#This Row],[TOTAL -10%]]*Tabla3[[#This Row],[NUBE]]) -> 0 | W40: SI | X40: FIDUCIA | Y40: 0.01 | Z40: 0.99 | AB40: =SUM(Y40:AA40) -> 1 | AC40: =IF(AB40="","",IF(AB40=100%,"OK","ERROR")) -> OK
A41: =(A40+1) -> 22 | B41: 1069720253 | C41: JHON JAIRO HERNANDEZ AYOLA | D41: 2 | E41: =(Tabla3[[#This Row],[CANT]]*5000000) -> 10000000 | F41: 1 | G41: 10000000 | R41: =(Tabla3[[#This Row],[MONTO]]+Tabla3[[#This Row],[MONTO2]]+Tabla3[[#This Row],[MONTO3]]+Tabla3[[#This Row],[MONTO4]]+Tabla3[[#This Row],[MONTO5]]+Tabla3[[#This Row],[MONTO6]]+Tabla3[[#This Row],[MONTO7]]) -> 20000000 | S41: =R41-(R41*10%) -> 18000000 | T41: =(S41*1%) -> 180000 | U41: =(Tabla3[[#This Row],[TOTAL -10%]]*Tabla3[[#This Row],[FIDUCIA]]) -> 17820000 | V41: =(Tabla3[[#This Row],[TOTAL -10%]]*Tabla3[[#This Row],[NUBE]]) -> 0 | W41: SI | X41: FIDUCIA | Y41: 0.01 | Z41: 0.99 | AB41: =SUM(Y41:AA41) -> 1 | AC41: =IF(AB41="","",IF(AB41=100%,"OK","ERROR")) -> OK
A42: =(A41+1) -> 23 | B42: 11310744 | C42: JHON SANCHEZ MARTINEZ | D42: 6 | E42: =(Tabla3[[#This Row],[CANT]]*5000000) -> 30000000 | F42: 2 | G42: 20000000 | H42: 3 | I42: 22500000 | R42: =(Tabla3[[#This Row],[MONTO]]+Tabla3[[#This Row],[MONTO2]]+Tabla3[[#This Row],[MONTO3]]+Tabla3[[#This Row],[MONTO4]]+Tabla3[[#This Row],[MONTO5]]+Tabla3[[#This Row],[MONTO6]]+Tabla3[[#This Row],[MONTO7]]) -> 72500000 | S42: =R42-(R42*10%) -> 65250000 | T42: =(S42*1%) -> 652500 | U42: =(Tabla3[[#This Row],[TOTAL -10%]]*Tabla3[[#This Row],[FIDUCIA]]) -> 64597500 | V42: =(Tabla3[[#This Row],[TOTAL -10%]]*Tabla3[[#This Row],[NUBE]]) -> 0 | W42: SI | X42: FIDUCIA | Y42: 0.01 | Z42: 0.99 | AB42: =SUM(Y42:AA42) -> 1 | AC42: =IF(AB42="","",IF(AB42=100%,"OK","ERROR")) -> OK
A43: =(A42+1) -> 24 | B43: 1000862511 | C43: JOSE LUIS RIAÑO OSPINA | D43: 2 | E43: =(Tabla3[[#This Row],[CANT]]*5000000) -> 10000000 | R43: =(Tabla3[[#This Row],[MONTO]]+Tabla3[[#This Row],[MONTO2]]+Tabla3[[#This Row],[MONTO3]]+Tabla3[[#This Row],[MONTO4]]+Tabla3[[#This Row],[MONTO5]]+Tabla3[[#This Row],[MONTO6]]+Tabla3[[#This Row],[MONTO7]]) -> 10000000 | S43: =R43-(R43*10%) -> 9000000 | T43: =(S43*1%) -> 90000 | U43: =(Tabla3[[#This Row],[TOTAL -10%]]*Tabla3[[#This Row],[FIDUCIA]]) -> 8910000 | V43: =(Tabla3[[#This Row],[TOTAL -10%]]*Tabla3[[#This Row],[NUBE]]) -> 0 | W43: SI | X43: FIDUCIA | Y43: 0.01 | Z43: 0.99 | AB43: =SUM(Y43:AA43) -> 1 | AC43: =IF(AB43="","",IF(AB43=100%,"OK","ERROR")) -> OK
A44: =(A43+1) -> 25 | B44: 11223744 | C44: JOSE MAURICIO VELASQUEZ TRUJILLO | D44: 9 | E44: =(Tabla3[[#This Row],[CANT]]*5000000) -> 45000000 | F44: 1 | G44: 10000000 | H44: 1 | I44: 7500000 | R44: =(Tabla3[[#This Row],[MONTO]]+Tabla3[[#This Row],[MONTO2]]+Tabla3[[#This Row],[MONTO3]]+Tabla3[[#This Row],[MONTO4]]+Tabla3[[#This Row],[MONTO5]]+Tabla3[[#This Row],[MONTO6]]+Tabla3[[#This Row],[MONTO7]]) -> 62500000 | S44: =R44-(R44*10%) -> 56250000 | T44: =(S44*1%) -> 562500 | U44: =(Tabla3[[#This Row],[TOTAL -10%]]*Tabla3[[#This Row],[FIDUCIA]]) -> 55687500 | V44: =(Tabla3[[#This Row],[TOTAL -10%]]*Tabla3[[#This Row],[NUBE]]) -> 0 | W44: SI | X44: FIDUCIA | Y44: 0.01 | Z44: 0.99 | AB44: =SUM(Y44:AA44) -> 1 | AC44: =IF(AB44="","",IF(AB44=100%,"OK","ERROR")) -> OK
A45: =(A44+1) -> 26 | B45: 79912646 | C45: JOSELITO OSPINA IZQUIERDO | D45: 8 | E45: =(Tabla3[[#This Row],[CANT]]*5000000) -> 40000000 | F45: 7 | G45: 70000000 | H45: 4 | I45: 30000000 | R45: =(Tabla3[[#This Row],[MONTO]]+Tabla3[[#This Row],[MONTO2]]+Tabla3[[#This Row],[MONTO3]]+Tabla3[[#This Row],[MONTO4]]+Tabla3[[#This Row],[MONTO5]]+Tabla3[[#This Row],[MONTO6]]+Tabla3[[#This Row],[MONTO7]]) -> 140000000 | S45: =R45-(R45*10%) -> 126000000 | T45: =(S45*1%) -> 1260000 | U45: =(Tabla3[[#This Row],[TOTAL -10%]]*Tabla3[[#This Row],[FIDUCIA]]) -> 124740000 | V45: =(Tabla3[[#This Row],[TOTAL -10%]]*Tabla3[[#This Row],[NUBE]]) -> 0 | W45: SI | X45: FIDUCIA | Y45: 0.01 | Z45: 0.99 | AB45: =SUM(Y45:AA45) -> 1 | AC45: =IF(AB45="","",IF(AB45=100%,"OK","ERROR")) -> OK
A46: =(A45+1) -> 27 | B46: 1018492143 | C46: LAURA DANIELA PARRA QUIROGA | D46: 4 | E46: =(Tabla3[[#This Row],[CANT]]*5000000) -> 20000000 | F46: 1 | G46: 10000000 | R46: =(Tabla3[[#This Row],[MONTO]]+Tabla3[[#This Row],[MONTO2]]+Tabla3[[#This Row],[MONTO3]]+Tabla3[[#This Row],[MONTO4]]+Tabla3[[#This Row],[MONTO5]]+Tabla3[[#This Row],[MONTO6]]+Tabla3[[#This Row],[MONTO7]]) -> 30000000 | S46: =R46-(R46*10%) -> 27000000 | T46: =(S46*1%) -> 270000 | U46: =(Tabla3[[#This Row],[TOTAL -10%]]*Tabla3[[#This Row],[FIDUCIA]]) -> 10800000 | V46: =(Tabla3[[#This Row],[TOTAL -10%]]*Tabla3[[#This Row],[NUBE]]) -> 15930000 | W46: SI | X46: FIDUCIA/NUBE | Y46: 0.01 | Z46: 0.4 | AA46: 0.59 | AB46: =SUM(Y46:AA46) -> 1 | AC46: =IF(AB46="","",IF(AB46=100%,"OK","ERROR")) -> OK
A47: =(A46+1) -> 28 | B47: 1034659000 | C47: LAURA TATIANA OSPINA SALAZAR | D47: 2 | E47: =(Tabla3[[#This Row],[CANT]]*5000000) -> 10000000 | R47: =(Tabla3[[#This Row],[MONTO]]+Tabla3[[#This Row],[MONTO2]]+Tabla3[[#This Row],[MONTO3]]+Tabla3[[#This Row],[MONTO4]]+Tabla3[[#This Row],[MONTO5]]+Tabla3[[#This Row],[MONTO6]]+Tabla3[[#This Row],[MONTO7]]) -> 10000000 | S47: =R47-(R47*10%) -> 9000000 | T47: =(S47*1%) -> 90000 | U47: =(Tabla3[[#This Row],[TOTAL -10%]]*Tabla3[[#This Row],[FIDUCIA]]) -> 8910000 | V47: =(Tabla3[[#This Row],[TOTAL -10%]]*Tabla3[[#This Row],[NUBE]]) -> 0 | W47: SI | X47: FIDUCIA | Y47: 0.01 | Z47: 0.99 | AB47: =SUM(Y47:AA47) -> 1 | AC47: =IF(AB47="","",IF(AB47=100%,"OK","ERROR")) -> OK
A48: =(A47+1) -> 29 | B48: 1014248041 | C48: LICETH ANDREA MARTINEZ HERNÁNDEZ | D48: 6 | E48: =(Tabla3[[#This Row],[CANT]]*5000000) -> 30000000 | R48: =(Tabla3[[#This Row],[MONTO]]+Tabla3[[#This Row],[MONTO2]]+Tabla3[[#This Row],[MONTO3]]+Tabla3[[#This Row],[MONTO4]]+Tabla3[[#This Row],[MONTO5]]+Tabla3[[#This Row],[MONTO6]]+Tabla3[[#This Row],[MONTO7]]) -> 30000000 | S48: =R48-(R48*10%) -> 27000000 | T48: =(S48*1%) -> 270000 | U48: =(Tabla3[[#This Row],[TOTAL -10%]]*Tabla3[[#This Row],[FIDUCIA]]) -> 26730000 | V48: =(Tabla3[[#This Row],[TOTAL -10%]]*Tabla3[[#This Row],[NUBE]]) -> 0 | W48: SI | X48: FIDUCIA | Y48: 0.01 | Z48: 0.99 | AB48: =SUM(Y48:AA48) -> 1 | AC48: =IF(AB48="","",IF(AB48=100%,"OK","ERROR")) -> OK
A49: =(A48+1) -> 30 | B49: 52286781 | C49: LUCIA OSPINA IZQUIERDO | D49: 2 | E49: =(Tabla3[[#This Row],[CANT]]*5000000) -> 10000000 | H49: 1 | I49: 7500000 | R49: =(Tabla3[[#This Row],[MONTO]]+Tabla3[[#This Row],[MONTO2]]+Tabla3[[#This Row],[MONTO3]]+Tabla3[[#This Row],[MONTO4]]+Tabla3[[#This Row],[MONTO5]]+Tabla3[[#This Row],[MONTO6]]+Tabla3[[#This Row],[MONTO7]]) -> 17500000 | S49: =R49-(R49*10%) -> 15750000 | T49: =(S49*1%) -> 157500 | U49: =(Tabla3[[#This Row],[TOTAL -10%]]*Tabla3[[#This Row],[FIDUCIA]]) -> 15592500 | V49: =(Tabla3[[#This Row],[TOTAL -10%]]*Tabla3[[#This Row],[NUBE]]) -> 0 | W49: SI | X49: FIDUCIA | Y49: 0.01 | Z49: 0.99 | AB49: =SUM(Y49:AA49) -> 1 | AC49: =IF(AB49="","",IF(AB49=100%,"OK","ERROR")) -> OK
A50: =(A49+1) -> 31 | B50: 3209263 | C50: LUIS EDGAR HERNANDEZ MARTÍNEZ | D50: 8 | E50: =(Tabla3[[#This Row],[CANT]]*5000000) -> 40000000 | F50: 1 | G50: 10000000 | H50: 1 | I50: 7500000 | R50: =(Tabla3[[#This Row],[MONTO]]+Tabla3[[#This Row],[MONTO2]]+Tabla3[[#This Row],[MONTO3]]+Tabla3[[#This Row],[MONTO4]]+Tabla3[[#This Row],[MONTO5]]+Tabla3[[#This Row],[MONTO6]]+Tabla3[[#This Row],[MONTO7]]) -> 57500000 | S50: =R50-(R50*10%) -> 51750000 | T50: =(S50*1%) -> 517500 | U50: =(Tabla3[[#This Row],[TOTAL -10%]]*Tabla3[[#This Row],[FIDUCIA]]) -> 0 | V50: =(Tabla3[[#This Row],[TOTAL -10%]]*Tabla3[[#This Row],[NUBE]]) -> 51232500 | W50: SI | X50: NUBE | Y50: 0.01 | AA50: 0.99 | AB50: =SUM(Y50:AA50) -> 1 | AC50: =IF(AB50="","",IF(AB50=100%,"OK","ERROR")) -> OK
A51: =(A50+1) -> 32 | B51: 79427033 | C51: LUIS EDUARDO BARRERA TORRES | D51: 4 | E51: =(Tabla3[[#This Row],[CANT]]*5000000) -> 20000000 | R51: =(Tabla3[[#This Row],[MONTO]]+Tabla3[[#This Row],[MONTO2]]+Tabla3[[#This Row],[MONTO3]]+Tabla3[[#This Row],[MONTO4]]+Tabla3[[#This Row],[MONTO5]]+Tabla3[[#This Row],[MONTO6]]+Tabla3[[#This Row],[MONTO7]]) -> 20000000 | S51: =R51-(R51*10%) -> 18000000 | T51: =(S51*1%) -> 180000 | U51: =(Tabla3[[#This Row],[TOTAL -10%]]*Tabla3[[#This Row],[FIDUCIA]]) -> 17820000 | V51: =(Tabla3[[#This Row],[TOTAL -10%]]*Tabla3[[#This Row],[NUBE]]) -> 0 | W51: SI | X51: FIDUCIA | Y51: 0.01 | Z51: 0.99 | AB51: =SUM(Y51:AA51) -> 1 | AC51: =IF(AB51="","",IF(AB51=100%,"OK","ERROR")) -> OK
A52: =(A51+1) -> 33 | B52: 11312576 | C52: LUIS EDUARDO PEREZ LOZANO | D52: 3 | E52: =(Tabla3[[#This Row],[CANT]]*5000000) -> 15000000 | R52: =(Tabla3[[#This Row],[MONTO]]+Tabla3[[#This Row],[MONTO2]]+Tabla3[[#This Row],[MONTO3]]+Tabla3[[#This Row],[MONTO4]]+Tabla3[[#This Row],[MONTO5]]+Tabla3[[#This Row],[MONTO6]]+Tabla3[[#This Row],[MONTO7]]) -> 15000000 | S52: =R52-(R52*10%) -> 13500000 | T52: =(S52*1%) -> 135000 | U52: =(Tabla3[[#This Row],[TOTAL -10%]]*Tabla3[[#This Row],[FIDUCIA]]) -> 13365000 | V52: =(Tabla3[[#This Row],[TOTAL -10%]]*Tabla3[[#This Row],[NUBE]]) -> 0 | W52: SI | X52: FIDUCIA | Y52: 0.01 | Z52: 0.99 | AB52: =SUM(Y52:AA52) -> 1 | AC52: =IF(AB52="","",IF(AB52=100%,"OK","ERROR")) -> OK
A53: =(A52+1) -> 34 | B53: 1003517850 | C53: MANUEL STEBAN VARGAS UBAQUE | D53: 2 | E53: =(Tabla3[[#This Row],[CANT]]*5000000) -> 10000000 | H53: 1 | I53: 7500000 | R53: =(Tabla3[[#This Row],[MONTO]]+Tabla3[[#This Row],[MONTO2]]+Tabla3[[#This Row],[MONTO3]]+Tabla3[[#This Row],[MONTO4]]+Tabla3[[#This Row],[MONTO5]]+Tabla3[[#This Row],[MONTO6]]+Tabla3[[#This Row],[MONTO7]]) -> 17500000 | S53: =R53-(R53*10%) -> 15750000 | T53: =(S53*1%) -> 157500 | U53: =(Tabla3[[#This Row],[TOTAL -10%]]*Tabla3[[#This Row],[FIDUCIA]]) -> 15592500 | V53: =(Tabla3[[#This Row],[TOTAL -10%]]*Tabla3[[#This Row],[NUBE]]) -> 0 | W53: SI | X53: FIDUCIA | Y53: 0.01 | Z53: 0.99 | AB53: =SUM(Y53:AA53) -> 1 | AC53: =IF(AB53="","",IF(AB53=100%,"OK","ERROR")) -> OK
...

Sheet RESUMEN INDIVIDUAL
O3: FECHA
O4: =TODAY() -> 46288
E5: LIDER: | F5: =('MATRIZ LISTADO'!D16) -> ELIZABETH QUIROGA | O5: Consulta con el valor del dólar (TRM) Aquí | Q5: https://www.dolar-colombia.com/
O6: 3192.92
E7: NOMBRE | F7: =IFERROR(VLOOKUP(F8,'MATRIZ LISTADO'!B19:C75,2,0),"") -> CARLOS ERNESTO PAZ CABAL | L7: =('RESUMEN INDIVIDUAL'!F7) -> CARLOS ERNESTO PAZ CABAL
E8: CC/ID/DNI | F8: 16266851 | L8: PAGO CON DESCUENTOS | P8: PESOS COLOMBIANOS
L9: PAGO TOTAL | O9: -0.1 | P9: =(G26*O6) -> 158049540000
L10: 0.01 | O10: BANCO | P10: =(I14*O6) -> 1580495400
F11: CANT | G11: PAGO | I11: ORDEN DE PAGOS | L11: =IFERROR(VLOOKUP(F8,'MATRIZ LISTADO'!B19:AB75,25,0),"") -> 0.99 | O11: FIDUCIA | P11: =(I18*O6) -> 156469044600
E12: QUINTILLION | F12: =IFERROR(VLOOKUP($F$8,Tabla3[[#All],[CC-ID-DNI]:[CANT]],3,0),"") -> 2 | G12: =(F12*5000000) -> 10000000 | I12: 1% PAGO BANCO | L12: =IFERROR(VLOOKUP(F8,'MATRIZ LISTADO'!B19:AB75,26,0),"") -> 0 | O12: NUBE | P12: =(I22*O6) -> 0
E14: NONGENTILLION | F14: =IFERROR(VLOOKUP($F$8,Tabla3[[CC-ID-DNI]:[1% PAGO INICIAL]],5,0),"") -> 3 | G14: =(F14*10000000) -> 30000000 | I14: =(G26*1%) -> 495000
E16: VIGINTILLION | F16: =IFERROR(VLOOKUP($F$8,Tabla3[[CC-ID-DNI]:[1% PAGO INICIAL]],7,0),"") -> 2 | G16: =(F16*7500000) -> 15000000 | I16: FIDUCIA
E18: MONEDA DE ZIM | F18: =IFERROR(VLOOKUP($F$8,Tabla3[[CC-ID-DNI]:[1% PAGO INICIAL]],9,0),"") -> 0 | G18: =(F18*500000) -> 0 | I18: =IFERROR(VLOOKUP(F8,Tabla3[[#All],[CC-ID-DNI]:[% NUBE]],20,0),"") -> 49005000
E20: AGROCHEQUE ZIM | F20: =IFERROR(VLOOKUP($F$8,Tabla3[[CC-ID-DNI]:[1% PAGO INICIAL]],13,0),"") -> 0 | G20: =(F20*200000) -> 0 | I20: NUBE
I22: =IFERROR(VLOOKUP(F8,Tabla3[[#All],[CC-ID-DNI]:[% NUBE]],21,0),"") -> 0
E24: TOTAL | G24: TOTAL -10%
E26: =SUM(G12:G22) -> 55000000 | G26: =E26-(E26*10%) -> 49500000
